Workbook
Name NAM: 'Danh mục'!$C$3
Name THANG: 'Tổng quan'!$F$3

Sheet Tổng quan
B1: ="TỔNG QUAN TÀI CHÍNH GIA ĐÌNH – THÁNG "&$F$3&"/"&NAM
B3: Năm: | C3: =NAM | E3: Chọn tháng ► | F3: 9 | G3: (bấm mũi tên chọn 1–12)
B5: Tổng thu nhập | C5: Chi tiêu | D5: Tích lũy & đầu tư | E5: Dòng tiền ròng | F5: Tỷ lệ tích lũy | G5: Chi cho con
B6: =INDEX('Báo cáo năm'!$D$16:$O$16,THANG) | C6: =INDEX('Báo cáo năm'!$D$86:$O$86,THANG) | D6: =INDEX('Báo cáo năm'!$D$87:$O$87,THANG) | E6: =INDEX('Báo cáo năm'!$D$88:$O$88,THANG) | F6: =IFERROR(D6/B6,0) | G6: =INDEX('Báo cáo năm'!$D$91:$O$91,THANG)
B7: ="Tháng "&THANG | C7: =IFERROR(C6/B6,0) | D7: =IFERROR(D6/B6,0) | E7: =IF(E6<0,"⚠ Chi vượt thu","✔ Thu ≥ chi") | F7: Nên ≥ 20% | G7: =IFERROR(G6/B6,0)
B8: =SUMPRODUCT(('Báo cáo năm'!$D$3:$O$3<=THANG)*'Báo cáo năm'!$D$16:$O$16) | C8: =SUMPRODUCT(('Báo cáo năm'!$D$3:$O$3<=THANG)*'Báo cáo năm'!$D$86:$O$86) | D8: =SUMPRODUCT(('Báo cáo năm'!$D$3:$O$3<=THANG)*'Báo cáo năm'!$D$87:$O$87) | E8: =SUMPRODUCT(('Báo cáo năm'!$D$3:$O$3<=THANG)*'Báo cáo năm'!$D$88:$O$88) | F8: =IFERROR(D8/B8,0) | G8: =SUMPRODUCT(('Báo cáo năm'!$D$3:$O$3<=THANG)*'Báo cáo năm'!$D$91:$O$91)
B10: PHÂN BỔ 6 HŨ TRONG THÁNG | J10: ="CHI TIẾT DANH MỤC CHI – THÁNG "&THANG
B11: Hũ | C11: Tỷ lệ | D11: Ngân sách | E11: Đã chi / đã nạp | F11: Còn lại | G11: % sử dụng | H11: Đánh giá | J11: Danh mục chi | K11: Hũ | L11: Hạn mức | M11: Thực chi | N11: Còn lại | O11: % hạn mức
B12: ='Danh mục'!B7 | C12: ='Danh mục'!C7 | D12: =INDEX('Báo cáo năm'!$D$22:$O$22,THANG) | E12: =INDEX('Báo cáo năm'!$D$23:$O$23,THANG) | F12: =D12-E12 | G12: =IFERROR(E12/D12,0) | H12: =IF(D12=0,"Chưa có thu nhập",IF('Danh mục'!D7="Tích lũy",IF(G12>=1,"✔ Đã nạp đủ","▲ Chưa nạp đủ"),IF(G12>1,"✖ Vượt ngân sách",IF(G12>=0.85,"▲ Sắp hết","✔ Trong ngân sách")))) | J12: ='Báo cáo năm'!B43 | K12: ='Báo cáo năm'!C43 | L12: =IF(N('Báo cáo năm'!R43)>0,'Báo cáo năm'!R43,"") | M12: =IF(J12="","",INDEX('Báo cáo năm'!$D$43:$O$43,THANG)) | N12: =IF(L12="","",L12-M12) | O12: =IF(L12="","",M12/L12)
B13: ='Danh mục'!B8 | C13: ='Danh mục'!C8 | D13: =INDEX('Báo cáo năm'!$D$25:$O$25,THANG) | E13: =INDEX('Báo cáo năm'!$D$26:$O$26,THANG) | F13: =D13-E13 | G13: =IFERROR(E13/D13,0) | H13: =IF(D13=0,"Chưa có thu nhập",IF('Danh mục'!D8="Tích lũy",IF(G13>=1,"✔ Đã nạp đủ","▲ Chưa nạp đủ"),IF(G13>1,"✖ Vượt ngân sách",IF(G13>=0.85,"▲ Sắp hết","✔ Trong ngân sách")))) | J13: ='Báo cáo năm'!B44 | K13: ='Báo cáo năm'!C44 | L13: =IF(N('Báo cáo năm'!R44)>0,'Báo cáo năm'!R44,"") | M13: =IF(J13="","",INDEX('Báo cáo năm'!$D$44:$O$44,THANG)) | N13: =IF(L13="","",L13-M13) | O13: =IF(L13="","",M13/L13)
B14: ='Danh mục'!B9 | C14: ='Danh mục'!C9 | D14: =INDEX('Báo cáo năm'!$D$28:$O$28,THANG) | E14: =INDEX('Báo cáo năm'!$D$29:$O$29,THANG) | F14: =D14-E14 | G14: =IFERROR(E14/D14,0) | H14: =IF(D14=0,"Chưa có thu nhập",IF('Danh mục'!D9="Tích lũy",IF(G14>=1,"✔ Đã nạp đủ","▲ Chưa nạp đủ"),IF(G14>1,"✖ Vượt ngân sách",IF(G14>=0.85,"▲ Sắp hết","✔ Trong ngân sách")))) | J14: ='Báo cáo năm'!B45 | K14: ='Báo cáo năm'!C45 | L14: =IF(N('Báo cáo năm'!R45)>0,'Báo cáo năm'!R45,"") | M14: =IF(J14="","",INDEX('Báo cáo năm'!$D$45:$O$45,THANG)) | N14: =IF(L14="","",L14-M14) | O14: =IF(L14="","",M14/L14)
B15: ='Danh mục'!B10 | C15: ='Danh mục'!C10 | D15: =INDEX('Báo cáo năm'!$D$31:$O$31,THANG) | E15: =INDEX('Báo cáo năm'!$D$32:$O$32,THANG) | F15: =D15-E15 | G15: =IFERROR(E15/D15,0) | H15: =IF(D15=0,"Chưa có thu nhập",IF('Danh mục'!D10="Tích lũy",IF(G15>=1,"✔ Đã nạp đủ","▲ Chưa nạp đủ"),IF(G15>1,"✖ Vượt ngân sách",IF(G15>=0.85,"▲ Sắp hết","✔ Trong ngân sách")))) | J15: ='Báo cáo năm'!B46 | K15: ='Báo cáo năm'!C46 | L15: =IF(N('Báo cáo năm'!R46)>0,'Báo cáo năm'!R46,"") | M15: =IF(J15="","",INDEX('Báo cáo năm'!$D$46:$O$46,THANG)) | N15: =IF(L15="","",L15-M15) | O15: =IF(L15="","",M15/L15)
B16: ='Danh mục'!B11 | C16: ='Danh mục'!C11 | D16: =INDEX('Báo cáo năm'!$D$34:$O$34,THANG) | E16: =INDEX('Báo cáo năm'!$D$35:$O$35,THANG) | F16: =D16-E16 | G16: =IFERROR(E16/D16,0) | H16: =IF(D16=0,"Chưa có thu nhập",IF('Danh mục'!D11="Tích lũy",IF(G16>=1,"✔ Đã nạp đủ","▲ Chưa nạp đủ"),IF(G16>1,"✖ Vượt ngân sách",IF(G16>=0.85,"▲ Sắp hết","✔ Trong ngân sách")))) | J16: ='Báo cáo năm'!B47 | K16: ='Báo cáo năm'!C47 | L16: =IF(N('Báo cáo năm'!R47)>0,'Báo cáo năm'!R47,"") | M16: =IF(J16="","",INDEX('Báo cáo năm'!$D$47:$O$47,THANG)) | N16: =IF(L16="","",L16-M16) | O16: =IF(L16="","",M16/L16)
B17: ='Danh mục'!B12 | C17: ='Danh mục'!C12 | D17: =INDEX('Báo cáo năm'!$D$37:$O$37,THANG) | E17: =INDEX('Báo cáo năm'!$D$38:$O$38,THANG) | F17: =D17-E17 | G17: =IFERROR(E17/D17,0) | H17: =IF(D17=0,"Chưa có thu nhập",IF('Danh mục'!D12="Tích lũy",IF(G17>=1,"✔ Đã nạp đủ","▲ Chưa nạp đủ"),IF(G17>1,"✖ Vượt ngân sách",IF(G17>=0.85,"▲ Sắp hết","✔ Trong ngân sách")))) | J17: ='Báo cáo năm'!B48 | K17: ='Báo cáo năm'!C48 | L17: =IF(N('Báo cáo năm'!R48)>0,'Báo cáo năm'!R48,"") | M17: =IF(J17="","",INDEX('Báo cáo năm'!$D$48:$O$48,THANG)) | N17: =IF(L17="","",L17-M17) | O17: =IF(L17="","",M17/L17)
B18: Tổng | C18: =SUM(C12:C17) | D18: =SUM(D12:D17) | E18: =SUM(E12:E17) | F18: =SUM(F12:F17) | G18: =IFERROR(E18/D18,0) | J18: ='Báo cáo năm'!B49 | K18: ='Báo cáo năm'!C49 | L18: =IF(N('Báo cáo năm'!R49)>0,'Báo cáo năm'!R49,"") | M18: =IF(J18="","",INDEX('Báo cáo năm'!$D$49:$O$49,THANG)) | N18: =IF(L18="","",L18-M18) | O18: =IF(L18="","",M18/L18)
J19: ='Báo cáo năm'!B50 | K19: ='Báo cáo năm'!C50 | L19: =IF(N('Báo cáo năm'!R50)>0,'Báo cáo năm'!R50,"") | M19: =IF(J19="","",INDEX('Báo cáo năm'!$D$50:$O$50,THANG)) | N19: =IF(L19="","",L19-M19) | O19: =IF(L19="","",M19/L19)
B20: NHẬN XÉT NHANH (tự động) | J20: ='Báo cáo năm'!B51 | K20: ='Báo cáo năm'!C51 | L20: =IF(N('Báo cáo năm'!R51)>0,'Báo cáo năm'!R51,"") | M20: =IF(J20="","",INDEX('Báo cáo năm'!$D$51:$O$51,THANG)) | N20: =IF(L20="","",L20-M20) | O20: =IF(L20="","",M20/L20)
B21: =IF(B6=0,"• Chưa có thu nhập trong tháng – ghi lương/thu nhập vào Sổ thu chi.",IF(F6>=0.2,"✔ Tỷ lệ tích lũy "&ROUND(F6*100,1)&"% – đạt khuyến nghị ≥ 20%.","▲ Tỷ lệ tích lũy "&ROUND(F6*100,1)&"% – dưới 20%: ngày nhận lương chuyển ngay tiền vào hũ Tích lũy trước khi tiêu.")) | J21: ='Báo cáo năm'!B52 | K21: ='Báo cáo năm'!C52 | L21: =IF(N('Báo cáo năm'!R52)>0,'Báo cáo năm'!R52,"") | M21: =IF(J21="","",INDEX('Báo cáo năm'!$D$52:$O$52,THANG)) | N21: =IF(L21="","",L21-M21) | O21: =IF(L21="","",M21/L21)
B22: =IF(E6<0,"✖ Chi vượt thu "&FIXED(-E6,0)&" đ – kiểm tra khoản chi lớn, tạm dừng chi Hưởng thụ.","✔ Dòng tiền dương "&FIXED(E6,0)&" đ – chuyển phần dư vào tiết kiệm/quỹ khẩn cấp.") | J22: ='Báo cáo năm'!B53 | K22: ='Báo cáo năm'!C53 | L22: =IF(N('Báo cáo năm'!R53)>0,'Báo cáo năm'!R53,"") | M22: =IF(J22="","",INDEX('Báo cáo năm'!$D$53:$O$53,THANG)) | N22: =IF(L22="","",L22-M22) | O22: =IF(L22="","",M22/L22)
B23: =IF(COUNTIF(H12:H17,"✖*")>0,"✖ Có "&COUNTIF(H12:H17,"✖*")&" hũ vượt ngân sách – xem bảng danh mục bên phải.","✔ Không hũ chi tiêu nào vượt ngân sách.") | J23: ='Báo cáo năm'!B54 | K23: ='Báo cáo năm'!C54 | L23: =IF(N('Báo cáo năm'!R54)>0,'Báo cáo năm'!R54,"") | M23: =IF(J23="","",INDEX('Báo cáo năm'!$D$54:$O$54,THANG)) | N23: =IF(L23="","",L23-M23) | O23: =IF(L23="","",M23/L23)
B24: =IF(COUNTIF(O12:O51,">1")>0,"✖ Có "&COUNTIF(O12:O51,">1")&" danh mục vượt hạn mức (tô đỏ ở bảng bên phải).","✔ Không danh mục nào vượt hạn mức đã đặt.") | J24: ='Báo cáo năm'!B55 | K24: ='Báo cáo năm'!C55 | L24: =IF(N('Báo cáo năm'!R55)>0,'Báo cáo năm'!R55,"") | M24: =IF(J24="","",INDEX('Báo cáo năm'!$D$55:$O$55,THANG)) | N24: =IF(L24="","",L24-M24) | O24: =IF(L24="","",M24/L24)
B25: =IF(B6=0,"",IF(E12/B6>0.55,"▲ Chi thiết yếu chiếm "&ROUND(E12/B6*100,1)&"% thu nhập (> 55%) – rà soát tiền nhà, ăn uống, đi lại.","✔ Chi thiết yếu chiếm "&ROUND(E12/B6*100,1)&"% thu nhập – trong mức 55%.")) | J25: ='Báo cáo năm'!B56 | K25: ='Báo cáo năm'!C56 | L25: =IF(N('Báo cáo năm'!R56)>0,'Báo cáo năm'!R56,"") | M25: =IF(J25="","",INDEX('Báo cáo năm'!$D$56:$O$56,THANG)) | N25: =IF(L25="","",L25-M25) | O25: =IF(L25="","",M25/L25)
J26: ='Báo cáo năm'!B57 | K26: ='Báo cáo năm'!C57 | L26: =IF(N('Báo cáo năm'!R57)>0,'Báo cáo năm'!R57,"") | M26: =IF(J26="","",INDEX('Báo cáo năm'!$D$57:$O$57,THANG)) | N26: =IF(L26="","",L26-M26) | O26: =IF(L26="","",M26/L26)
J27: ='Báo cáo năm'!B58 | K27: ='Báo cáo năm'!C58 | L27: =IF(N('Báo cáo năm'!R58)>0,'Báo cáo năm'!R58,"") | M27: =IF(J27="","",INDEX('Báo cáo năm'!$D$58:$O$58,THANG)) | N27: =IF(L27="","",L27-M27) | O27: =IF(L27="","",M27/L27)
J28: ='Báo cáo năm'!B59 | K28: ='Báo cáo năm'!C59 | L28: =IF(N('Báo cáo năm'!R59)>0,'Báo cáo năm'!R59,"") | M28: =IF(J28="","",INDEX('Báo cáo năm'!$D$59:$O$59,THANG)) | N28: =IF(L28="","",L28-M28) | O28: =IF(L28="","",M28/L28)
J29: ='Báo cáo năm'!B60 | K29: ='Báo cáo năm'!C60 | L29: =IF(N('Báo cáo năm'!R60)>0,'Báo cáo năm'!R60,"") | M29: =IF(J29="","",INDEX('Báo cáo năm'!$D$60:$O$60,THANG)) | N29: =IF(L29="","",L29-M29) | O29: =IF(L29="","",M29/L29)
J30: ='Báo cáo năm'!B61 | K30: ='Báo cáo năm'!C61 | L30: =IF(N('Báo cáo năm'!R61)>0,'Báo cáo năm'!R61,"") | M30: =IF(J30="","",INDEX('Báo cáo năm'!$D$61:$O$61,THANG)) | N30: =IF(L30="","",L30-M30) | O30: =IF(L30="","",M30/L30)
J31: ='Báo cáo năm'!B62 | K31: ='Báo cáo năm'!C62 | L31: =IF(N('Báo cáo năm'!R62)>0,'Báo cáo năm'!R62,"") | M31: =IF(J31="","",INDEX('Báo cáo năm'!$D$62:$O$62,THANG)) | N31: =IF(L31="","",L31-M31) | O31: =IF(L31="","",M31/L31)
J32: ='Báo cáo năm'!B63 | K32: ='Báo cáo năm'!C63 | L32: =IF(N('Báo cáo năm'!R63)>0,'Báo cáo năm'!R63,"") | M32: =IF(J32="","",INDEX('Báo cáo năm'!$D$63:$O$63,THANG)) | N32: =IF(L32="","",L32-M32) | O32: =IF(L32="","",M32/L32)
J33: ='Báo cáo năm'!B64 | K33: ='Báo cáo năm'!C64 | L33: =IF(N('Báo cáo năm'!R64)>0,'Báo cáo năm'!R64,"") | M33: =IF(J33="","",INDEX('Báo cáo năm'!$D$64:$O$64,THANG)) | N33: =IF(L33="","",L33-M33) | O33: =IF(L33="","",M33/L33)
J34: ='Báo cáo năm'!B65 | K34: ='Báo cáo năm'!C65 | L34: =IF(N('Báo cáo năm'!R65)>0,'Báo cáo năm'!R65,"") | M34: =IF(J34="","",INDEX('Báo cáo năm'!$D$65:$O$65,THANG)) | N34: =IF(L34="","",L34-M34) | O34: =IF(L34="","",M34/L34)
J35: ='Báo cáo năm'!B66 | K35: ='Báo cáo năm'!C66 | L35: =IF(N('Báo cáo năm'!R66)>0,'Báo cáo năm'!R66,"") | M35: =IF(J35="","",INDEX('Báo cáo năm'!$D$66:$O$66,THANG)) | N35: =IF(L35="","",L35-M35) | O35: =IF(L35="","",M35/L35)
J36: ='Báo cáo năm'!B67 | K36: ='Báo cáo năm'!C67 | L36: =IF(N('Báo cáo năm'!R67)>0,'Báo cáo năm'!R67,"") | M36: =IF(J36="","",INDEX('Báo cáo năm'!$D$67:$O$67,THANG)) | N36: =IF(L36="","",L36-M36) | O36: =IF(L36="","",M36/L36)
J37: ='Báo cáo năm'!B68 | K37: ='Báo cáo năm'!C68 | L37: =IF(N('Báo cáo năm'!R68)>0,'Báo cáo năm'!R68,"") | M37: =IF(J37="","",INDEX('Báo cáo năm'!$D$68:$O$68,THANG)) | N37: =IF(L37="","",L37-M37) | O37: =IF(L37="","",M37/L37)
J38: ='Báo cáo năm'!B69 | K38: ='Báo cáo năm'!C69 | L38: =IF(N('Báo cáo năm'!R69)>0,'Báo cáo năm'!R69,"") | M38: =IF(J38="","",INDEX('Báo cáo năm'!$D$69:$O$69,THANG)) | N38: =IF(L38="","",L38-M38) | O38: =IF(L38="","",M38/L38)
J39: ='Báo cáo năm'!B70 | K39: ='Báo cáo năm'!C70 | L39: =IF(N('Báo cáo năm'!R70)>0,'Báo cáo năm'!R70,"") | M39: =IF(J39="","",INDEX('Báo cáo năm'!$D$70:$O$70,THANG)) | N39: =IF(L39="","",L39-M39) | O39: =IF(L39="","",M39/L39)
J40: ='Báo cáo năm'!B71 | K40: ='Báo cáo năm'!C71 | L40: =IF(N('Báo cáo năm'!R71)>0,'Báo cáo năm'!R71,"") | M40: =IF(J40="","",INDEX('Báo cáo năm'!$D$71:$O$71,THANG)) | N40: =IF(L40="","",L40-M40) | O40: =IF(L40="","",M40/L40)
J41: ='Báo cáo năm'!B72 | K41: ='Báo cáo năm'!C72 | L41: =IF(N('Báo cáo năm'!R72)>0,'Báo cáo năm'!R72,"") | M41: =IF(J41="","",INDEX('Báo cáo năm'!$D$72:$O$72,THANG)) | N41: =IF(L41="","",L41-M41) | O41: =IF(L41="","",M41/L41)
J42: ='Báo cáo năm'!B73 | K42: ='Báo cáo năm'!C73 | L42: =IF(N('Báo cáo năm'!R73)>0,'Báo cáo năm'!R73,"") | M42: =IF(J42="","",INDEX('Báo cáo năm'!$D$73:$O$73,THANG)) | N42: =IF(L42="","",L42-M42) | O42: =IF(L42="","",M42/L42)
J43: ='Báo cáo năm'!B74 | K43: ='Báo cáo năm'!C74 | L43: =IF(N('Báo cáo năm'!R74)>0,'Báo cáo năm'!R74,"") | M43: =IF(J43="","",INDEX('Báo cáo năm'!$D$74:$O$74,THANG)) | N43: =IF(L43="","",L43-M43) | O43: =IF(L43="","",M43/L43)
...

Sheet Sổ thu chi
A1: SỔ THU CHI GIA ĐÌNH
A4: Ngày | B4: Tháng (tự động) | C4: Loại | D4: Danh mục | E4: Hũ (tự động) | F4: Tính chất (tự động) | G4: Nhóm (tự động) | H4: Nội dung | I4: Số tiền (VNĐ) | J4: Người | K4: Hình thức TT | L4: Ghi chú
B5: =IF(A5="","",DATE(YEAR(A5),MONTH(A5),1)) | E5: =IF(OR(D5="",C5<>"Chi"),"",IFERROR(INDEX('Danh mục'!$B$39:$B$78,MATCH(D5,'Danh mục'!$A$39:$A$78,0))&"","?")) | F5: =IF(D5="","",IF(C5="Thu",IFERROR(INDEX('Danh mục'!$B$26:$B$35,MATCH(D5,'Danh mục'!$A$26:$A$35,0))&"","?"),IFERROR(INDEX('Danh mục'!$D$39:$D$78,MATCH(D5,'Danh mục'!$A$39:$A$78,0))&"","?"))) | G5: =IF(OR(D5="",C5<>"Chi"),"",IFERROR(INDEX('Danh mục'!$C$39:$C$78,MATCH(D5,'Danh mục'!$A$39:$A$78,0))&"",""))
B6: =IF(A6="","",DATE(YEAR(A6),MONTH(A6),1)) | E6: =IF(OR(D6="",C6<>"Chi"),"",IFERROR(INDEX('Danh mục'!$B$39:$B$78,MATCH(D6,'Danh mục'!$A$39:$A$78,0))&"","?")) | F6: =IF(D6="","",IF(C6="Thu",IFERROR(INDEX('Danh mục'!$B$26:$B$35,MATCH(D6,'Danh mục'!$A$26:$A$35,0))&"","?"),IFERROR(INDEX('Danh mục'!$D$39:$D$78,MATCH(D6,'Danh mục'!$A$39:$A$78,0))&"","?"))) | G6: =IF(OR(D6="",C6<>"Chi"),"",IFERROR(INDEX('Danh mục'!$C$39:$C$78,MATCH(D6,'Danh mục'!$A$39:$A$78,0))&"",""))
B7: =IF(A7="","",DATE(YEAR(A7),MONTH(A7),1)) | E7: =IF(OR(D7="",C7<>"Chi"),"",IFERROR(INDEX('Danh mục'!$B$39:$B$78,MATCH(D7,'Danh mục'!$A$39:$A$78,0))&"","?")) | F7: =IF(D7="","",IF(C7="Thu",IFERROR(INDEX('Danh mục'!$B$26:$B$35,MATCH(D7,'Danh mục'!$A$26:$A$35,0))&"","?"),IFERROR(INDEX('Danh mục'!$D$39:$D$78,MATCH(D7,'Danh mục'!$A$39:$A$78,0))&"","?"))) | G7: =IF(OR(D7="",C7<>"Chi"),"",IFERROR(INDEX('Danh mục'!$C$39:$C$78,MATCH(D7,'Danh mục'!$A$39:$A$78,0))&"",""))
B8: =IF(A8="","",DATE(YEAR(A8),MONTH(A8),1)) | E8: =IF(OR(D8="",C8<>"Chi"),"",IFERROR(INDEX('Danh mục'!$B$39:$B$78,MATCH(D8,'Danh mục'!$A$39:$A$78,0))&"","?")) | F8: =IF(D8="","",IF(C8="Thu",IFERROR(INDEX('Danh mục'!$B$26:$B$35,MATCH(D8,'Danh mục'!$A$26:$A$35,0))&"","?"),IFERROR(INDEX('Danh mục'!$D$39:$D$78,MATCH(D8,'Danh mục'!$A$39:$A$78,0))&"","?"))) | G8: =IF(OR(D8="",C8<>"Chi"),"",IFERROR(INDEX('Danh mục'!$C$39:$C$78,MATCH(D8,'Danh mục'!$A$39:$A$78,0))&"",""))
B9: =IF(A9="","",DATE(YEAR(A9),MONTH(A9),1)) | E9: =IF(OR(D9="",C9<>"Chi"),"",IFERROR(INDEX('Danh mục'!$B$39:$B$78,MATCH(D9,'Danh mục'!$A$39:$A$78,0))&"","?")) | F9: =IF(D9="","",IF(C9="Thu",IFERROR(INDEX('Danh mục'!$B$26:$B$35,MATCH(D9,'Danh mục'!$A$26:$A$35,0))&"","?"),IFERROR(INDEX('Danh mục'!$D$39:$D$78,MATCH(D9,'Danh mục'!$A$39:$A$78,0))&"","?"))) | G9: =IF(OR(D9="",C9<>"Chi"),"",IFERROR(INDEX('Danh mục'!$C$39:$C$78,MATCH(D9,'Danh mục'!$A$39:$A$78,0))&"",""))
B10: =IF(A10="","",DATE(YEAR(A10),MONTH(A10),1)) | E10: =IF(OR(D10="",C10<>"Chi"),"",IFERROR(INDEX('Danh mục'!$B$39:$B$78,MATCH(D10,'Danh mục'!$A$39:$A$78,0))&"","?")) | F10: =IF(D10="","",IF(C10="Thu",IFERROR(INDEX('Danh mục'!$B$26:$B$35,MATCH(D10,'Danh mục'!$A$26:$A$35,0))&"","?"),IFERROR(INDEX('Danh mục'!$D$39:$D$78,MATCH(D10,'Danh mục'!$A$39:$A$78,0))&"","?"))) | G10: =IF(OR(D10="",C10<>"Chi"),"",IFERROR(INDEX('Danh mục'!$C$39:$C$78,MATCH(D10,'Danh mục'!$A$39:$A$78,0))&"",""))
B11: =IF(A11="","",DATE(YEAR(A11),MONTH(A11),1)) | E11: =IF(OR(D11="",C11<>"Chi"),"",IFERROR(INDEX('Danh mục'!$B$39:$B$78,MATCH(D11,'Danh mục'!$A$39:$A$78,0))&"","?")) | F11: =IF(D11="","",IF(C11="Thu",IFERROR(INDEX('Danh mục'!$B$26:$B$35,MATCH(D11,'Danh mục'!$A$26:$A$35,0))&"","?"),IFERROR(INDEX('Danh mục'!$D$39:$D$78,MATCH(D11,'Danh mục'!$A$39:$A$78,0))&"","?"))) | G11: =IF(OR(D11="",C11<>"Chi"),"",IFERROR(INDEX('Danh mục'!$C$39:$C$78,MATCH(D11,'Danh mục'!$A$39:$A$78,0))&"",""))
B12: =IF(A12="","",DATE(YEAR(A12),MONTH(A12),1)) | E12: =IF(OR(D12="",C12<>"Chi"),"",IFERROR(INDEX('Danh mục'!$B$39:$B$78,MATCH(D12,'Danh mục'!$A$39:$A$78,0))&"","?")) | F12: =IF(D12="","",IF(C12="Thu",IFERROR(INDEX('Danh mục'!$B$26:$B$35,MATCH(D12,'Danh mục'!$A$26:$A$35,0))&"","?"),IFERROR(INDEX('Danh mục'!$D$39:$D$78,MATCH(D12,'Danh mục'!$A$39:$A$78,0))&"","?"))) | G12: =IF(OR(D12="",C12<>"Chi"),"",IFERROR(INDEX('Danh mục'!$C$39:$C$78,MATCH(D12,'Danh mục'!$A$39:$A$78,0))&"",""))
B13: =IF(A13="","",DATE(YEAR(A13),MONTH(A13),1)) | E13: =IF(OR(D13="",C13<>"Chi"),"",IFERROR(INDEX('Danh mục'!$B$39:$B$78,MATCH(D13,'Danh mục'!$A$39:$A$78,0))&"","?")) | F13: =IF(D13="","",IF(C13="Thu",IFERROR(INDEX('Danh mục'!$B$26:$B$35,MATCH(D13,'Danh mục'!$A$26:$A$35,0))&"","?"),IFERROR(INDEX('Danh mục'!$D$39:$D$78,MATCH(D13,'Danh mục'!$A$39:$A$78,0))&"","?"))) | G13: =IF(OR(D13="",C13<>"Chi"),"",IFERROR(INDEX('Danh mục'!$C$39:$C$78,MATCH(D13,'Danh mục'!$A$39:$A$78,0))&"",""))
B14: =IF(A14="","",DATE(YEAR(A14),MONTH(A14),1)) | E14: =IF(OR(D14="",C14<>"Chi"),"",IFERROR(INDEX('Danh mục'!$B$39:$B$78,MATCH(D14,'Danh mục'!$A$39:$A$78,0))&"","?")) | F14: =IF(D14="","",IF(C14="Thu",IFERROR(INDEX('Danh mục'!$B$26:$B$35,MATCH(D14,'Danh mục'!$A$26:$A$35,0))&"","?"),IFERROR(INDEX('Danh mục'!$D$39:$D$78,MATCH(D14,'Danh mục'!$A$39:$A$78,0))&"","?"))) | G14: =IF(OR(D14="",C14<>"Chi"),"",IFERROR(INDEX('Danh mục'!$C$39:$C$78,MATCH(D14,'Danh mục'!$A$39:$A$78,0))&"",""))
B15: =IF(A15="","",DATE(YEAR(A15),MONTH(A15),1)) | E15: =IF(OR(D15="",C15<>"Chi"),"",IFERROR(INDEX('Danh mục'!$B$39:$B$78,MATCH(D15,'Danh mục'!$A$39:$A$78,0))&"","?")) | F15: =IF(D15="","",IF(C15="Thu",IFERROR(INDEX('Danh mục'!$B$26:$B$35,MATCH(D15,'Danh mục'!$A$26:$A$35,0))&"","?"),IFERROR(INDEX('Danh mục'!$D$39:$D$78,MATCH(D15,'Danh mục'!$A$39:$A$78,0))&"","?"))) | G15: =IF(OR(D15="",C15<>"Chi"),"",IFERROR(INDEX('Danh mục'!$C$39:$C$78,MATCH(D15,'Danh mục'!$A$39:$A$78,0))&"",""))
B16: =IF(A16="","",DATE(YEAR(A16),MONTH(A16),1)) | E16: =IF(OR(D16="",C16<>"Chi"),"",IFERROR(INDEX('Danh mục'!$B$39:$B$78,MATCH(D16,'Danh mục'!$A$39:$A$78,0))&"","?")) | F16: =IF(D16="","",IF(C16="Thu",IFERROR(INDEX('Danh mục'!$B$26:$B$35,MATCH(D16,'Danh mục'!$A$26:$A$35,0))&"","?"),IFERROR(INDEX('Danh mục'!$D$39:$D$78,MATCH(D16,'Danh mục'!$A$39:$A$78,0))&"","?"))) | G16: =IF(OR(D16="",C16<>"Chi"),"",IFERROR(INDEX('Danh mục'!$C$39:$C$78,MATCH(D16,'Danh mục'!$A$39:$A$78,0))&"",""))
... B1979: =IF(A1979="","",DATE(YEAR(A1979),MONTH(A1979),1)) | E1979: =IF(OR(D1979="",C1979<>"Chi"),"",IFERROR(INDEX('Danh mục'!$B$39:$B$78,MATCH(D1979,'Danh mục'!$A$39:$A$78,0))&"","?")) | F1979: =IF(D1979="","",IF(C1979="Thu",IFERROR(INDEX('Danh mục'!$B$26:$B$35,MATCH(D1979,'Danh mục'!$A$26:$A$35,0))&"","?"),IFERROR(INDEX('Danh mục'!$D$39:$D$78,MATCH(D1979,'Danh mục'!$A$39:$A$78,0))&"","?"))) | G1979: =IF(OR(D1979="",C1979<>"Chi"),"",IFERROR(INDEX('Danh mục'!$C$39:$C$78,MATCH(D1979,'Danh mục'!$A$39:$A$78,0))&"",""))

Sheet Báo cáo năm
A1: ="BÁO CÁO THU CHI GIA ĐÌNH NĂM "&NAM
A2: Tự tính từ Sổ thu chi – không cần nhập. Ô đỏ = vượt ngân sách hũ / vượt hạn mức / dòng tiền âm; ô vàng = tỷ lệ tích lũy < 20%.
D3: 1 | E3: 2 | F3: 3 | G3: 4 | H3: 5 | I3: 6 | J3: 7 | K3: 8 | L3: 9 | M3: 10 | N3: 11 | O3: 12
A4: STT | B4: Khoản mục | C4: Hũ / Tính chất | D4: ="T"&D$3&"/"&NAM | E4: ="T"&E$3&"/"&NAM | F4: ="T"&F$3&"/"&NAM | G4: ="T"&G$3&"/"&NAM | H4: ="T"&H$3&"/"&NAM | I4: ="T"&I$3&"/"&NAM | J4: ="T"&J$3&"/"&NAM | K4: ="T"&K$3&"/"&NAM | ... O4: ="T"&O$3&"/"&NAM | P4: Cả năm | Q4: TB/tháng | R4: Hạn mức/tháng
A5: I. THU NHẬP
A6: 1 | B6: =IF('Danh mục'!A26="","",'Danh mục'!A26) | C6: ='Danh mục'!B26&"" | D6: =IF($B6="",0,SUMIFS('Sổ thu chi'!$I$5:$I$1979,'Sổ thu chi'!$B$5:$B$1979,DATE(NAM,D$3,1),'Sổ thu chi'!$C$5:$C$1979,"Thu",'Sổ thu chi'!$D$5:$D$1979,$B6)) | E6: =IF($B6="",0,SUMIFS('Sổ thu chi'!$I$5:$I$1979,'Sổ thu chi'!$B$5:$B$1979,DATE(NAM,E$3,1),'Sổ thu chi'!$C$5:$C$1979,"Thu",'Sổ thu chi'!$D$5:$D$1979,$B6)) | F6: =IF($B6="",0,SUMIFS('Sổ thu chi'!$I$5:$I$1979,'Sổ thu chi'!$B$5:$B$1979,DATE(NAM,F$3,1),'Sổ thu chi'!$C$5:$C$1979,"Thu",'Sổ thu chi'!$D$5:$D$1979,$B6)) | G6: =IF($B6="",0,SUMIFS('Sổ thu chi'!$I$5:$I$1979,'Sổ thu chi'!$B$5:$B$1979,DATE(NAM,G$3,1),'Sổ thu chi'!$C$5:$C$1979,"Thu",'Sổ thu chi'!$D$5:$D$1979,$B6)) | H6: =IF($B6="",0,SUMIFS('Sổ thu chi'!$I$5:$I$1979,'Sổ thu chi'!$B$5:$B$1979,DATE(NAM,H$3,1),'Sổ thu chi'!$C$5:$C$1979,"Thu",'Sổ thu chi'!$D$5:$D$1979,$B6)) | I6: =IF($B6="",0,SUMIFS('Sổ thu chi'!$I$5:$I$1979,'Sổ thu chi'!$B$5:$B$1979,DATE(NAM,I$3,1),'Sổ thu chi'!$C$5:$C$1979,"Thu",'Sổ thu chi'!$D$5:$D$1979,$B6)) | J6: =IF($B6="",0,SUMIFS('Sổ thu chi'!$I$5:$I$1979,'Sổ thu chi'!$B$5:$B$1979,DATE(NAM,J$3,1),'Sổ thu chi'!$C$5:$C$1979,"Thu",'Sổ thu chi'!$D$5:$D$1979,$B6)) | K6: =IF($B6="",0,SUMIFS('Sổ thu chi'!$I$5:$I$1979,'Sổ thu chi'!$B$5:$B$1979,DATE(NAM,K$3,1),'Sổ thu chi'!$C$5:$C$1979,"Thu",'Sổ thu chi'!$D$5:$D$1979,$B6)) | ... O6: =IF($B6="",0,SUMIFS('Sổ thu chi'!$I$5:$I$1979,'Sổ thu chi'!$B$5:$B$1979,DATE(NAM,O$3,1),'Sổ thu chi'!$C$5:$C$1979,"Thu",'Sổ thu chi'!$D$5:$D$1979,$B6)) | P6: =SUM(D6:O6) | Q6: =IFERROR(AVERAGEIF(D6:O6,"<>0"),0)
A7: 2 | B7: =IF('Danh mục'!A27="","",'Danh mục'!A27) | C7: ='Danh mục'!B27&"" | D7: =IF($B7="",0,SUMIFS('Sổ thu chi'!$I$5:$I$1979,'Sổ thu chi'!$B$5:$B$1979,DATE(NAM,D$3,1),'Sổ thu chi'!$C$5:$C$1979,"Thu",'Sổ thu chi'!$D$5:$D$1979,$B7)) | E7: =IF($B7="",0,SUMIFS('Sổ thu chi'!$I$5:$I$1979,'Sổ thu chi'!$B$5:$B$1979,DATE(NAM,E$3,1),'Sổ thu chi'!$C$5:$C$1979,"Thu",'Sổ thu chi'!$D$5:$D$1979,$B7)) | F7: =IF($B7="",0,SUMIFS('Sổ thu chi'!$I$5:$I$1979,'Sổ thu chi'!$B$5:$B$1979,DATE(NAM,F$3,1),'Sổ thu chi'!$C$5:$C$1979,"Thu",'Sổ thu chi'!$D$5:$D$1979,$B7)) | G7: =IF($B7="",0,SUMIFS('Sổ thu chi'!$I$5:$I$1979,'Sổ thu chi'!$B$5:$B$1979,DATE(NAM,G$3,1),'Sổ thu chi'!$C$5:$C$1979,"Thu",'Sổ thu chi'!$D$5:$D$1979,$B7)) | H7: =IF($B7="",0,SUMIFS('Sổ thu chi'!$I$5:$I$1979,'Sổ thu chi'!$B$5:$B$1979,DATE(NAM,H$3,1),'Sổ thu chi'!$C$5:$C$1979,"Thu",'Sổ thu chi'!$D$5:$D$1979,$B7)) | I7: =IF($B7="",0,SUMIFS('Sổ thu chi'!$I$5:$I$1979,'Sổ thu chi'!$B$5:$B$1979,DATE(NAM,I$3,1),'Sổ thu chi'!$C$5:$C$1979,"Thu",'Sổ thu chi'!$D$5:$D$1979,$B7)) | J7: =IF($B7="",0,SUMIFS('Sổ thu chi'!$I$5:$I$1979,'Sổ thu chi'!$B$5:$B$1979,DATE(NAM,J$3,1),'Sổ thu chi'!$C$5:$C$1979,"Thu",'Sổ thu chi'!$D$5:$D$1979,$B7)) | K7: =IF($B7="",0,SUMIFS('Sổ thu chi'!$I$5:$I$1979,'Sổ thu chi'!$B$5:$B$1979,DATE(NAM,K$3,1),'Sổ thu chi'!$C$5:$C$1979,"Thu",'Sổ thu chi'!$D$5:$D$1979,$B7)) | ... O7: =IF($B7="",0,SUMIFS('Sổ thu chi'!$I$5:$I$1979,'Sổ thu chi'!$B$5:$B$1979,DATE(NAM,O$3,1),'Sổ thu chi'!$C$5:$C$1979,"Thu",'Sổ thu chi'!$D$5:$D$1979,$B7)) | P7: =SUM(D7:O7) | Q7: =IFERROR(AVERAGEIF(D7:O7,"<>0"),0)
A8: 3 | B8: =IF('Danh mục'!A28="","",'Danh mục'!A28) | C8: ='Danh mục'!B28&"" | D8: =IF($B8="",0,SUMIFS('Sổ thu chi'!$I$5:$I$1979,'Sổ thu chi'!$B$5:$B$1979,DATE(NAM,D$3,1),'Sổ thu chi'!$C$5:$C$1979,"Thu",'Sổ thu chi'!$D$5:$D$1979,$B8)) | E8: =IF($B8="",0,SUMIFS('Sổ thu chi'!$I$5:$I$1979,'Sổ thu chi'!$B$5:$B$1979,DATE(NAM,E$3,1),'Sổ thu chi'!$C$5:$C$1979,"Thu",'Sổ thu chi'!$D$5:$D$1979,$B8)) | F8: =IF($B8="",0,SUMIFS('Sổ thu chi'!$I$5:$I$1979,'Sổ thu chi'!$B$5:$B$1979,DATE(NAM,F$3,1),'Sổ thu chi'!$C$5:$C$1979,"Thu",'Sổ thu chi'!$D$5:$D$1979,$B8)) | G8: =IF($B8="",0,SUMIFS('Sổ thu chi'!$I$5:$I$1979,'Sổ thu chi'!$B$5:$B$1979,DATE(NAM,G$3,1),'Sổ thu chi'!$C$5:$C$1979,"Thu",'Sổ thu chi'!$D$5:$D$1979,$B8)) | H8: =IF($B8="",0,SUMIFS('Sổ thu chi'!$I$5:$I$1979,'Sổ thu chi'!$B$5:$B$1979,DATE(NAM,H$3,1),'Sổ thu chi'!$C$5:$C$1979,"Thu",'Sổ thu chi'!$D$5:$D$1979,$B8)) | I8: =IF($B8="",0,SUMIFS('Sổ thu chi'!$I$5:$I$1979,'Sổ thu chi'!$B$5:$B$1979,DATE(NAM,I$3,1),'Sổ thu chi'!$C$5:$C$1979,"Thu",'Sổ thu chi'!$D$5:$D$1979,$B8)) | J8: =IF($B8="",0,SUMIFS('Sổ thu chi'!$I$5:$I$1979,'Sổ thu chi'!$B$5:$B$1979,DATE(NAM,J$3,1),'Sổ thu chi'!$C$5:$C$1979,"Thu",'Sổ thu chi'!$D$5:$D$1979,$B8)) | K8: =IF($B8="",0,SUMIFS('Sổ thu chi'!$I$5:$I$1979,'Sổ thu chi'!$B$5:$B$1979,DATE(NAM,K$3,1),'Sổ thu chi'!$C$5:$C$1979,"Thu",'Sổ thu chi'!$D$5:$D$1979,$B8)) | ... O8: =IF($B8="",0,SUMIFS('Sổ thu chi'!$I$5:$I$1979,'Sổ thu chi'!$B$5:$B$1979,DATE(NAM,O$3,1),'Sổ thu chi'!$C$5:$C$1979,"Thu",'Sổ thu chi'!$D$5:$D$1979,$B8)) | P8: =SUM(D8:O8) | Q8: =IFERROR(AVERAGEIF(D8:O8,"<>0"),0)
A9: 4 | B9: =IF('Danh mục'!A29="","",'Danh mục'!A29) | C9: ='Danh mục'!B29&"" | D9: =IF($B9="",0,SUMIFS('Sổ thu chi'!$I$5:$I$1979,'Sổ thu chi'!$B$5:$B$1979,DATE(NAM,D$3,1),'Sổ thu chi'!$C$5:$C$1979,"Thu",'Sổ thu chi'!$D$5:$D$1979,$B9)) | E9: =IF($B9="",0,SUMIFS('Sổ thu chi'!$I$5:$I$1979,'Sổ thu chi'!$B$5:$B$1979,DATE(NAM,E$3,1),'Sổ thu chi'!$C$5:$C$1979,"Thu",'Sổ thu chi'!$D$5:$D$1979,$B9)) | F9: =IF($B9="",0,SUMIFS('Sổ thu chi'!$I$5:$I$1979,'Sổ thu chi'!$B$5:$B$1979,DATE(NAM,F$3,1),'Sổ thu chi'!$C$5:$C$1979,"Thu",'Sổ thu chi'!$D$5:$D$1979,$B9)) | G9: =IF($B9="",0,SUMIFS('Sổ thu chi'!$I$5:$I$1979,'Sổ thu chi'!$B$5:$B$1979,DATE(NAM,G$3,1),'Sổ thu chi'!$C$5:$C$1979,"Thu",'Sổ thu chi'!$D$5:$D$1979,$B9)) | H9: =IF($B9="",0,SUMIFS('Sổ thu chi'!$I$5:$I$1979,'Sổ thu chi'!$B$5:$B$1979,DATE(NAM,H$3,1),'Sổ thu chi'!$C$5:$C$1979,"Thu",'Sổ thu chi'!$D$5:$D$1979,$B9)) | I9: =IF($B9="",0,SUMIFS('Sổ thu chi'!$I$5:$I$1979,'Sổ thu chi'!$B$5:$B$1979,DATE(NAM,I$3,1),'Sổ thu chi'!$C$5:$C$1979,"Thu",'Sổ thu chi'!$D$5:$D$1979,$B9)) | J9: =IF($B9="",0,SUMIFS('Sổ thu chi'!$I$5:$I$1979,'Sổ thu chi'!$B$5:$B$1979,DATE(NAM,J$3,1),'Sổ thu chi'!$C$5:$C$1979,"Thu",'Sổ thu chi'!$D$5:$D$1979,$B9)) | K9: =IF($B9="",0,SUMIFS('Sổ thu chi'!$I$5:$I$1979,'Sổ thu chi'!$B$5:$B$1979,DATE(NAM,K$3,1),'Sổ thu chi'!$C$5:$C$1979,"Thu",'Sổ thu chi'!$D$5:$D$1979,$B9)) | ... O9: =IF($B9="",0,SUMIFS('Sổ thu chi'!$I$5:$I$1979,'Sổ thu chi'!$B$5:$B$1979,DATE(NAM,O$3,1),'Sổ thu chi'!$C$5:$C$1979,"Thu",'Sổ thu chi'!$D$5:$D$1979,$B9)) | P9: =SUM(D9:O9) | Q9: =IFERROR(AVERAGEIF(D9:O9,"<>0"),0)
A10: 5 | B10: =IF('Danh mục'!A30="","",'Danh mục'!A30) | C10: ='Danh mục'!B30&"" | D10: =IF($B10="",0,SUMIFS('Sổ thu chi'!$I$5:$I$1979,'Sổ thu chi'!$B$5:$B$1979,DATE(NAM,D$3,1),'Sổ thu chi'!$C$5:$C$1979,"Thu",'Sổ thu chi'!$D$5:$D$1979,$B10)) | E10: =IF($B10="",0,SUMIFS('Sổ thu chi'!$I$5:$I$1979,'Sổ thu chi'!$B$5:$B$1979,DATE(NAM,E$3,1),'Sổ thu chi'!$C$5:$C$1979,"Thu",'Sổ thu chi'!$D$5:$D$1979,$B10)) | F10: =IF($B10="",0,SUMIFS('Sổ thu chi'!$I$5:$I$1979,'Sổ thu chi'!$B$5:$B$1979,DATE(NAM,F$3,1),'Sổ thu chi'!$C$5:$C$1979,"Thu",'Sổ thu chi'!$D$5:$D$1979,$B10)) | G10: =IF($B10="",0,SUMIFS('Sổ thu chi'!$I$5:$I$1979,'Sổ thu chi'!$B$5:$B$1979,DATE(NAM,G$3,1),'Sổ thu chi'!$C$5:$C$1979,"Thu",'Sổ thu chi'!$D$5:$D$1979,$B10)) | H10: =IF($B10="",0,SUMIFS('Sổ thu chi'!$I$5:$I$1979,'Sổ thu chi'!$B$5:$B$1979,DATE(NAM,H$3,1),'Sổ thu chi'!$C$5:$C$1979,"Thu",'Sổ thu chi'!$D$5:$D$1979,$B10)) | I10: =IF($B10="",0,SUMIFS('Sổ thu chi'!$I$5:$I$1979,'Sổ thu chi'!$B$5:$B$1979,DATE(NAM,I$3,1),'Sổ thu chi'!$C$5:$C$1979,"Thu",'Sổ thu chi'!$D$5:$D$1979,$B10)) | J10: =IF($B10="",0,SUMIFS('Sổ thu chi'!$I$5:$I$1979,'Sổ thu chi'!$B$5:$B$1979,DATE(NAM,J$3,1),'Sổ thu chi'!$C$5:$C$1979,"Thu",'Sổ thu chi'!$D$5:$D$1979,$B10)) | K10: =IF($B10="",0,SUMIFS('Sổ thu chi'!$I$5:$I$1979,'Sổ thu chi'!$B$5:$B$1979,DATE(NAM,K$3,1),'Sổ thu chi'!$C$5:$C$1979,"Thu",'Sổ thu chi'!$D$5:$D$1979,$B10)) | ... O10: =IF($B10="",0,SUMIFS('Sổ thu chi'!$I$5:$I$1979,'Sổ thu chi'!$B$5:$B$1979,DATE(NAM,O$3,1),'Sổ thu chi'!$C$5:$C$1979,"Thu",'Sổ thu chi'!$D$5:$D$1979,$B10)) | P10: =SUM(D10:O10) | Q10: =IFERROR(AVERAGEIF(D10:O10,"<>0"),0)
A11: 6 | B11: =IF('Danh mục'!A31="","",'Danh mục'!A31) | C11: ='Danh mục'!B31&"" | D11: =IF($B11="",0,SUMIFS('Sổ thu chi'!$I$5:$I$1979,'Sổ thu chi'!$B$5:$B$1979,DATE(NAM,D$3,1),'Sổ thu chi'!$C$5:$C$1979,"Thu",'Sổ thu chi'!$D$5:$D$1979,$B11)) | E11: =IF($B11="",0,SUMIFS('Sổ thu chi'!$I$5:$I$1979,'Sổ thu chi'!$B$5:$B$1979,DATE(NAM,E$3,1),'Sổ thu chi'!$C$5:$C$1979,"Thu",'Sổ thu chi'!$D$5:$D$1979,$B11)) | F11: =IF($B11="",0,SUMIFS('Sổ thu chi'!$I$5:$I$1979,'Sổ thu chi'!$B$5:$B$1979,DATE(NAM,F$3,1),'Sổ thu chi'!$C$5:$C$1979,"Thu",'Sổ thu chi'!$D$5:$D$1979,$B11)) | G11: =IF($B11="",0,SUMIFS('Sổ thu chi'!$I$5:$I$1979,'Sổ thu chi'!$B$5:$B$1979,DATE(NAM,G$3,1),'Sổ thu chi'!$C$5:$C$1979,"Thu",'Sổ thu chi'!$D$5:$D$1979,$B11)) | H11: =IF($B11="",0,SUMIFS('Sổ thu chi'!$I$5:$I$1979,'Sổ thu chi'!$B$5:$B$1979,DATE(NAM,H$3,1),'Sổ thu chi'!$C$5:$C$1979,"Thu",'Sổ thu chi'!$D$5:$D$1979,$B11)) | I11: =IF($B11="",0,SUMIFS('Sổ thu chi'!$I$5:$I$1979,'Sổ thu chi'!$B$5:$B$1979,DATE(NAM,I$3,1),'Sổ thu chi'!$C$5:$C$1979,"Thu",'Sổ thu chi'!$D$5:$D$1979,$B11)) | J11: =IF($B11="",0,SUMIFS('Sổ thu chi'!$I$5:$I$1979,'Sổ thu chi'!$B$5:$B$1979,DATE(NAM,J$3,1),'Sổ thu chi'!$C$5:$C$1979,"Thu",'Sổ thu chi'!$D$5:$D$1979,$B11)) | K11: =IF($B11="",0,SUMIFS('Sổ thu chi'!$I$5:$I$1979,'Sổ thu chi'!$B$5:$B$1979,DATE(NAM,K$3,1),'Sổ thu chi'!$C$5:$C$1979,"Thu",'Sổ thu chi'!$D$5:$D$1979,$B11)) | ... O11: =IF($B11="",0,SUMIFS('Sổ thu chi'!$I$5:$I$1979,'Sổ thu chi'!$B$5:$B$1979,DATE(NAM,O$3,1),'Sổ thu chi'!$C$5:$C$1979,"Thu",'Sổ thu chi'!$D$5:$D$1979,$B11)) | P11: =SUM(D11:O11) | Q11: =IFERROR(AVERAGEIF(D11:O11,"<>0"),0)
A12: 7 | B12: =IF('Danh mục'!A32="","",'Danh mục'!A32) | C12: ='Danh mục'!B32&"" | D12: =IF($B12="",0,SUMIFS('Sổ thu chi'!$I$5:$I$1979,'Sổ thu chi'!$B$5:$B$1979,DATE(NAM,D$3,1),'Sổ thu chi'!$C$5:$C$1979,"Thu",'Sổ thu chi'!$D$5:$D$1979,$B12)) | E12: =IF($B12="",0,SUMIFS('Sổ thu chi'!$I$5:$I$1979,'Sổ thu chi'!$B$5:$B$1979,DATE(NAM,E$3,1),'Sổ thu chi'!$C$5:$C$1979,"Thu",'Sổ thu chi'!$D$5:$D$1979,$B12)) | F12: =IF($B12="",0,SUMIFS('Sổ thu chi'!$I$5:$I$1979,'Sổ thu chi'!$B$5:$B$1979,DATE(NAM,F$3,1),'Sổ thu chi'!$C$5:$C$1979,"Thu",'Sổ thu chi'!$D$5:$D$1979,$B12)) | G12: =IF($B12="",0,SUMIFS('Sổ thu chi'!$I$5:$I$1979,'Sổ thu chi'!$B$5:$B$1979,DATE(NAM,G$3,1),'Sổ thu chi'!$C$5:$C$1979,"Thu",'Sổ thu chi'!$D$5:$D$1979,$B12)) | H12: =IF($B12="",0,SUMIFS('Sổ thu chi'!$I$5:$I$1979,'Sổ thu chi'!$B$5:$B$1979,DATE(NAM,H$3,1),'Sổ thu chi'!$C$5:$C$1979,"Thu",'Sổ thu chi'!$D$5:$D$1979,$B12)) | I12: =IF($B12="",0,SUMIFS('Sổ thu chi'!$I$5:$I$1979,'Sổ thu chi'!$B$5:$B$1979,DATE(NAM,I$3,1),'Sổ thu chi'!$C$5:$C$1979,"Thu",'Sổ thu chi'!$D$5:$D$1979,$B12)) | J12: =IF($B12="",0,SUMIFS('Sổ thu chi'!$I$5:$I$1979,'Sổ thu chi'!$B$5:$B$1979,DATE(NAM,J$3,1),'Sổ thu chi'!$C$5:$C$1979,"Thu",'Sổ thu chi'!$D$5:$D$1979,$B12)) | K12: =IF($B12="",0,SUMIFS('Sổ thu chi'!$I$5:$I$1979,'Sổ thu chi'!$B$5:$B$1979,DATE(NAM,K$3,1),'Sổ thu chi'!$C$5:$C$1979,"Thu",'Sổ thu chi'!$D$5:$D$1979,$B12)) | ... O12: =IF($B12="",0,SUMIFS('Sổ thu chi'!$I$5:$I$1979,'Sổ thu chi'!$B$5:$B$1979,DATE(NAM,O$3,1),'Sổ thu chi'!$C$5:$C$1979,"Thu",'Sổ thu chi'!$D$5:$D$1979,$B12)) | P12: =SUM(D12:O12) | Q12: =IFERROR(AVERAGEIF(D12:O12,"<>0"),0)
A13: 8 | B13: =IF('Danh mục'!A33="","",'Danh mục'!A33) | C13: ='Danh mục'!B33&"" | D13: =IF($B13="",0,SUMIFS('Sổ thu chi'!$I$5:$I$1979,'Sổ thu chi'!$B$5:$B$1979,DATE(NAM,D$3,1),'Sổ thu chi'!$C$5:$C$1979,"Thu",'Sổ thu chi'!$D$5:$D$1979,$B13)) | E13: =IF($B13="",0,SUMIFS('Sổ thu chi'!$I$5:$I$1979,'Sổ thu chi'!$B$5:$B$1979,DATE(NAM,E$3,1),'Sổ thu chi'!$C$5:$C$1979,"Thu",'Sổ thu chi'!$D$5:$D$1979,$B13)) | F13: =IF($B13="",0,SUMIFS('Sổ thu chi'!$I$5:$I$1979,'Sổ thu chi'!$B$5:$B$1979,DATE(NAM,F$3,1),'Sổ thu chi'!$C$5:$C$1979,"Thu",'Sổ thu chi'!$D$5:$D$1979,$B13)) | G13: =IF($B13="",0,SUMIFS('Sổ thu chi'!$I$5:$I$1979,'Sổ thu chi'!$B$5:$B$1979,DATE(NAM,G$3,1),'Sổ thu chi'!$C$5:$C$1979,"Thu",'Sổ thu chi'!$D$5:$D$1979,$B13)) | H13: =IF($B13="",0,SUMIFS('Sổ thu chi'!$I$5:$I$1979,'Sổ thu chi'!$B$5:$B$1979,DATE(NAM,H$3,1),'Sổ thu chi'!$C$5:$C$1979,"Thu",'Sổ thu chi'!$D$5:$D$1979,$B13)) | I13: =IF($B13="",0,SUMIFS('Sổ thu chi'!$I$5:$I$1979,'Sổ thu chi'!$B$5:$B$1979,DATE(NAM,I$3,1),'Sổ thu chi'!$C$5:$C$1979,"Thu",'Sổ thu chi'!$D$5:$D$1979,$B13)) | J13: =IF($B13="",0,SUMIFS('Sổ thu chi'!$I$5:$I$1979,'Sổ thu chi'!$B$5:$B$1979,DATE(NAM,J$3,1),'Sổ thu chi'!$C$5:$C$1979,"Thu",'Sổ thu chi'!$D$5:$D$1979,$B13)) | K13: =IF($B13="",0,SUMIFS('Sổ thu chi'!$I$5:$I$1979,'Sổ thu chi'!$B$5:$B$1979,DATE(NAM,K$3,1),'Sổ thu chi'!$C$5:$C$1979,"Thu",'Sổ thu chi'!$D$5:$D$1979,$B13)) | ... O13: =IF($B13="",0,SUMIFS('Sổ thu chi'!$I$5:$I$1979,'Sổ thu chi'!$B$5:$B$1979,DATE(NAM,O$3,1),'Sổ thu chi'!$C$5:$C$1979,"Thu",'Sổ thu chi'!$D$5:$D$1979,$B13)) | P13: =SUM(D13:O13) | Q13: =IFERROR(AVERAGEIF(D13:O13,"<>0"),0)
A14: 9 | B14: =IF('Danh mục'!A34="","",'Danh mục'!A34) | C14: ='Danh mục'!B34&"" | D14: =IF($B14="",0,SUMIFS('Sổ thu chi'!$I$5:$I$1979,'Sổ thu chi'!$B$5:$B$1979,DATE(NAM,D$3,1),'Sổ thu chi'!$C$5:$C$1979,"Thu",'Sổ thu chi'!$D$5:$D$1979,$B14)) | E14: =IF($B14="",0,SUMIFS('Sổ thu chi'!$I$5:$I$1979,'Sổ thu chi'!$B$5:$B$1979,DATE(NAM,E$3,1),'Sổ thu chi'!$C$5:$C$1979,"Thu",'Sổ thu chi'!$D$5:$D$1979,$B14)) | F14: =IF($B14="",0,SUMIFS('Sổ thu chi'!$I$5:$I$1979,'Sổ thu chi'!$B$5:$B$1979,DATE(NAM,F$3,1),'Sổ thu chi'!$C$5:$C$1979,"Thu",'Sổ thu chi'!$D$5:$D$1979,$B14)) | G14: =IF($B14="",0,SUMIFS('Sổ thu chi'!$I$5:$I$1979,'Sổ thu chi'!$B$5:$B$1979,DATE(NAM,G$3,1),'Sổ thu chi'!$C$5:$C$1979,"Thu",'Sổ thu chi'!$D$5:$D$1979,$B14)) | H14: =IF($B14="",0,SUMIFS('Sổ thu chi'!$I$5:$I$1979,'Sổ thu chi'!$B$5:$B$1979,DATE(NAM,H$3,1),'Sổ thu chi'!$C$5:$C$1979,"Thu",'Sổ thu chi'!$D$5:$D$1979,$B14)) | I14: =IF($B14="",0,SUMIFS('Sổ thu chi'!$I$5:$I$1979,'Sổ thu chi'!$B$5:$B$1979,DATE(NAM,I$3,1),'Sổ thu chi'!$C$5:$C$1979,"Thu",'Sổ thu chi'!$D$5:$D$1979,$B14)) | J14: =IF($B14="",0,SUMIFS('Sổ thu chi'!$I$5:$I$1979,'Sổ thu chi'!$B$5:$B$1979,DATE(NAM,J$3,1),'Sổ thu chi'!$C$5:$C$1979,"Thu",'Sổ thu chi'!$D$5:$D$1979,$B14)) | K14: =IF($B14="",0,SUMIFS('Sổ thu chi'!$I$5:$I$1979,'Sổ thu chi'!$B$5:$B$1979,DATE(NAM,K$3,1),'Sổ thu chi'!$C$5:$C$1979,"Thu",'Sổ thu chi'!$D$5:$D$1979,$B14)) | ... O14: =IF($B14="",0,SUMIFS('Sổ thu chi'!$I$5:$I$1979,'Sổ thu chi'!$B$5:$B$1979,DATE(NAM,O$3,1),'Sổ thu chi'!$C$5:$C$1979,"Thu",'Sổ thu chi'!$D$5:$D$1979,$B14)) | P14: =SUM(D14:O14) | Q14: =IFERROR(AVERAGEIF(D14:O14,"<>0"),0)
A15: 10 | B15: =IF('Danh mục'!A35="","",'Danh mục'!A35) | C15: ='Danh mục'!B35&"" | D15: =IF($B15="",0,SUMIFS('Sổ thu chi'!$I$5:$I$1979,'Sổ thu chi'!$B$5:$B$1979,DATE(NAM,D$3,1),'Sổ thu chi'!$C$5:$C$1979,"Thu",'Sổ thu chi'!$D$5:$D$1979,$B15)) | E15: =IF($B15="",0,SUMIFS('Sổ thu chi'!$I$5:$I$1979,'Sổ thu chi'!$B$5:$B$1979,DATE(NAM,E$3,1),'Sổ thu chi'!$C$5:$C$1979,"Thu",'Sổ thu chi'!$D$5:$D$1979,$B15)) | F15: =IF($B15="",0,SUMIFS('Sổ thu chi'!$I$5:$I$1979,'Sổ thu chi'!$B$5:$B$1979,DATE(NAM,F$3,1),'Sổ thu chi'!$C$5:$C$1979,"Thu",'Sổ thu chi'!$D$5:$D$1979,$B15)) | G15: =IF($B15="",0,SUMIFS('Sổ thu chi'!$I$5:$I$1979,'Sổ thu chi'!$B$5:$B$1979,DATE(NAM,G$3,1),'Sổ thu chi'!$C$5:$C$1979,"Thu",'Sổ thu chi'!$D$5:$D$1979,$B15)) | H15: =IF($B15="",0,SUMIFS('Sổ thu chi'!$I$5:$I$1979,'Sổ thu chi'!$B$5:$B$1979,DATE(NAM,H$3,1),'Sổ thu chi'!$C$5:$C$1979,"Thu",'Sổ thu chi'!$D$5:$D$1979,$B15)) | I15: =IF($B15="",0,SUMIFS('Sổ thu chi'!$I$5:$I$1979,'Sổ thu chi'!$B$5:$B$1979,DATE(NAM,I$3,1),'Sổ thu chi'!$C$5:$C$1979,"Thu",'Sổ thu chi'!$D$5:$D$1979,$B15)) | J15: =IF($B15="",0,SUMIFS('Sổ thu chi'!$I$5:$I$1979,'Sổ thu chi'!$B$5:$B$1979,DATE(NAM,J$3,1),'Sổ thu chi'!$C$5:$C$1979,"Thu",'Sổ thu chi'!$D$5:$D$1979,$B15)) | K15: =IF($B15="",0,SUMIFS('Sổ thu chi'!$I$5:$I$1979,'Sổ thu chi'!$B$5:$B$1979,DATE(NAM,K$3,1),'Sổ thu chi'!$C$5:$C$1979,"Thu",'Sổ thu chi'!$D$5:$D$1979,$B15)) | ... O15: =IF($B15="",0,SUMIFS('Sổ thu chi'!$I$5:$I$1979,'Sổ thu chi'!$B$5:$B$1979,DATE(NAM,O$3,1),'Sổ thu chi'!$C$5:$C$1979,"Thu",'Sổ thu chi'!$D$5:$D$1979,$B15)) | P15: =SUM(D15:O15) | Q15: =IFERROR(AVERAGEIF(D15:O15,"<>0"),0)
B16: Tổng thu nhập (dùng chia 6 hũ) | D16: =SUMIFS('Sổ thu chi'!$I$5:$I$1979,'Sổ thu chi'!$B$5:$B$1979,DATE(NAM,D$3,1),'Sổ thu chi'!$C$5:$C$1979,"Thu",'Sổ thu chi'!$F$5:$F$1979,"Thu nhập") | E16: =SUMIFS('Sổ thu chi'!$I$5:$I$1979,'Sổ thu chi'!$B$5:$B$1979,DATE(NAM,E$3,1),'Sổ thu chi'!$C$5:$C$1979,"Thu",'Sổ thu chi'!$F$5:$F$1979,"Thu nhập") | F16: =SUMIFS('Sổ thu chi'!$I$5:$I$1979,'Sổ thu chi'!$B$5:$B$1979,DATE(NAM,F$3,1),'Sổ thu chi'!$C$5:$C$1979,"Thu",'Sổ thu chi'!$F$5:$F$1979,"Thu nhập") | G16: =SUMIFS('Sổ thu chi'!$I$5:$I$1979,'Sổ thu chi'!$B$5:$B$1979,DATE(NAM,G$3,1),'Sổ thu chi'!$C$5:$C$1979,"Thu",'Sổ thu chi'!$F$5:$F$1979,"Thu nhập") | H16: =SUMIFS('Sổ thu chi'!$I$5:$I$1979,'Sổ thu chi'!$B$5:$B$1979,DATE(NAM,H$3,1),'Sổ thu chi'!$C$5:$C$1979,"Thu",'Sổ thu chi'!$F$5:$F$1979,"Thu nhập") | I16: =SUMIFS('Sổ thu chi'!$I$5:$I$1979,'Sổ thu chi'!$B$5:$B$1979,DATE(NAM,I$3,1),'Sổ thu chi'!$C$5:$C$1979,"Thu",'Sổ thu chi'!$F$5:$F$1979,"Thu nhập") | J16: =SUMIFS('Sổ thu chi'!$I$5:$I$1979,'Sổ thu chi'!$B$5:$B$1979,DATE(NAM,J$3,1),'Sổ thu chi'!$C$5:$C$1979,"Thu",'Sổ thu chi'!$F$5:$F$1979,"Thu nhập") | K16: =SUMIFS('Sổ thu chi'!$I$5:$I$1979,'Sổ thu chi'!$B$5:$B$1979,DATE(NAM,K$3,1),'Sổ thu chi'!$C$5:$C$1979,"Thu",'Sổ thu chi'!$F$5:$F$1979,"Thu nhập") | ... O16: =SUMIFS('Sổ thu chi'!$I$5:$I$1979,'Sổ thu chi'!$B$5:$B$1979,DATE(NAM,O$3,1),'Sổ thu chi'!$C$5:$C$1979,"Thu",'Sổ thu chi'!$F$5:$F$1979,"Thu nhập") | P16: =SUM(D16:O16) | Q16: =IFERROR(AVERAGEIF(D16:O16,"<>0"),0)
B17: Rút tiền tiết kiệm | D17: =SUMIFS('Sổ thu chi'!$I$5:$I$1979,'Sổ thu chi'!$B$5:$B$1979,DATE(NAM,D$3,1),'Sổ thu chi'!$C$5:$C$1979,"Thu",'Sổ thu chi'!$F$5:$F$1979,"Rút quỹ") | E17: =SUMIFS('Sổ thu chi'!$I$5:$I$1979,'Sổ thu chi'!$B$5:$B$1979,DATE(NAM,E$3,1),'Sổ thu chi'!$C$5:$C$1979,"Thu",'Sổ thu chi'!$F$5:$F$1979,"Rút quỹ") | F17: =SUMIFS('Sổ thu chi'!$I$5:$I$1979,'Sổ thu chi'!$B$5:$B$1979,DATE(NAM,F$3,1),'Sổ thu chi'!$C$5:$C$1979,"Thu",'Sổ thu chi'!$F$5:$F$1979,"Rút quỹ") | G17: =SUMIFS('Sổ thu chi'!$I$5:$I$1979,'Sổ thu chi'!$B$5:$B$1979,DATE(NAM,G$3,1),'Sổ thu chi'!$C$5:$C$1979,"Thu",'Sổ thu chi'!$F$5:$F$1979,"Rút quỹ") | H17: =SUMIFS('Sổ thu chi'!$I$5:$I$1979,'Sổ thu chi'!$B$5:$B$1979,DATE(NAM,H$3,1),'Sổ thu chi'!$C$5:$C$1979,"Thu",'Sổ thu chi'!$F$5:$F$1979,"Rút quỹ") | I17: =SUMIFS('Sổ thu chi'!$I$5:$I$1979,'Sổ thu chi'!$B$5:$B$1979,DATE(NAM,I$3,1),'Sổ thu chi'!$C$5:$C$1979,"Thu",'Sổ thu chi'!$F$5:$F$1979,"Rút quỹ") | J17: =SUMIFS('Sổ thu chi'!$I$5:$I$1979,'Sổ thu chi'!$B$5:$B$1979,DATE(NAM,J$3,1),'Sổ thu chi'!$C$5:$C$1979,"Thu",'Sổ thu chi'!$F$5:$F$1979,"Rút quỹ") | K17: =SUMIFS('Sổ thu chi'!$I$5:$I$1979,'Sổ thu chi'!$B$5:$B$1979,DATE(NAM,K$3,1),'Sổ thu chi'!$C$5:$C$1979,"Thu",'Sổ thu chi'!$F$5:$F$1979,"Rút quỹ") | ... O17: =SUMIFS('Sổ thu chi'!$I$5:$I$1979,'Sổ thu chi'!$B$5:$B$1979,DATE(NAM,O$3,1),'Sổ thu chi'!$C$5:$C$1979,"Thu",'Sổ thu chi'!$F$5:$F$1979,"Rút quỹ") | P17: =SUM(D17:O17) | Q17: =IFERROR(AVERAGEIF(D17:O17,"<>0"),0)
B18: TỔNG THU | D18: =D16+D17 | E18: =E16+E17 | F18: =F16+F17 | G18: =G16+G17 | H18: =H16+H17 | I18: =I16+I17 | J18: =J16+J17 | K18: =K16+K17 | ... O18: =O16+O17 | P18: =SUM(D18:O18) | Q18: =IFERROR(AVERAGEIF(D18:O18,"<>0"),0)
A20: II. 6 HŨ: NGÂN SÁCH (= Thu nhập × tỷ lệ) – THỰC CHI – CÒN LẠI
B21: Hũ | C21: Tỷ lệ / Loại
A22: 1 | B22: ='Danh mục'!B7&" – Ngân sách" | C22: ='Danh mục'!C7 | D22: =D$16*'Danh mục'!$C$7 | E22: =E$16*'Danh mục'!$C$7 | F22: =F$16*'Danh mục'!$C$7 | G22: =G$16*'Danh mục'!$C$7 | H22: =H$16*'Danh mục'!$C$7 | I22: =I$16*'Danh mục'!$C$7 | J22: =J$16*'Danh mục'!$C$7 | K22: =K$16*'Danh mục'!$C$7 | ... O22: =O$16*'Danh mục'!$C$7 | P22: =SUM(D22:O22) | Q22: =IFERROR(AVERAGEIF(D22:O22,"<>0"),0)
B23: Thực chi / đã nạp | C23: ='Danh mục'!D7 | D23: =SUMIFS('Sổ thu chi'!$I$5:$I$1979,'Sổ thu chi'!$B$5:$B$1979,DATE(NAM,D$3,1),'Sổ thu chi'!$C$5:$C$1979,"Chi",'Sổ thu chi'!$E$5:$E$1979,'Danh mục'!$B$7) | E23: =SUMIFS('Sổ thu chi'!$I$5:$I$1979,'Sổ thu chi'!$B$5:$B$1979,DATE(NAM,E$3,1),'Sổ thu chi'!$C$5:$C$1979,"Chi",'Sổ thu chi'!$E$5:$E$1979,'Danh mục'!$B$7) | F23: =SUMIFS('Sổ thu chi'!$I$5:$I$1979,'Sổ thu chi'!$B$5:$B$1979,DATE(NAM,F$3,1),'Sổ thu chi'!$C$5:$C$1979,"Chi",'Sổ thu chi'!$E$5:$E$1979,'Danh mục'!$B$7) | G23: =SUMIFS('Sổ thu chi'!$I$5:$I$1979,'Sổ thu chi'!$B$5:$B$1979,DATE(NAM,G$3,1),'Sổ thu chi'!$C$5:$C$1979,"Chi",'Sổ thu chi'!$E$5:$E$1979,'Danh mục'!$B$7) | H23: =SUMIFS('Sổ thu chi'!$I$5:$I$1979,'Sổ thu chi'!$B$5:$B$1979,DATE(NAM,H$3,1),'Sổ thu chi'!$C$5:$C$1979,"Chi",'Sổ thu chi'!$E$5:$E$1979,'Danh mục'!$B$7) | I23: =SUMIFS('Sổ thu chi'!$I$5:$I$1979,'Sổ thu chi'!$B$5:$B$1979,DATE(NAM,I$3,1),'Sổ thu chi'!$C$5:$C$1979,"Chi",'Sổ thu chi'!$E$5:$E$1979,'Danh mục'!$B$7) | J23: =SUMIFS('Sổ thu chi'!$I$5:$I$1979,'Sổ thu chi'!$B$5:$B$1979,DATE(NAM,J$3,1),'Sổ thu chi'!$C$5:$C$1979,"Chi",'Sổ thu chi'!$E$5:$E$1979,'Danh mục'!$B$7) | K23: =SUMIFS('Sổ thu chi'!$I$5:$I$1979,'Sổ thu chi'!$B$5:$B$1979,DATE(NAM,K$3,1),'Sổ thu chi'!$C$5:$C$1979,"Chi",'Sổ thu chi'!$E$5:$E$1979,'Danh mục'!$B$7) | ... O23: =SUMIFS('Sổ thu chi'!$I$5:$I$1979,'Sổ thu chi'!$B$5:$B$1979,DATE(NAM,O$3,1),'Sổ thu chi'!$C$5:$C$1979,"Chi",'Sổ thu chi'!$E$5:$E$1979,'Danh mục'!$B$7) | P23: =SUM(D23:O23) | Q23: =IFERROR(AVERAGEIF(D23:O23,"<>0"),0)
B24: Còn lại | D24: =D22-D23 | E24: =E22-E23 | F24: =F22-F23 | G24: =G22-G23 | H24: =H22-H23 | I24: =I22-I23 | J24: =J22-J23 | K24: =K22-K23 | ... O24: =O22-O23 | P24: =SUM(D24:O24)
A25: 2 | B25: ='Danh mục'!B8&" – Ngân sách" | C25: ='Danh mục'!C8 | D25: =D$16*'Danh mục'!$C$8 | E25: =E$16*'Danh mục'!$C$8 | F25: =F$16*'Danh mục'!$C$8 | G25: =G$16*'Danh mục'!$C$8 | H25: =H$16*'Danh mục'!$C$8 | I25: =I$16*'Danh mục'!$C$8 | J25: =J$16*'Danh mục'!$C$8 | K25: =K$16*'Danh mục'!$C$8 | ... O25: =O$16*'Danh mục'!$C$8 | P25: =SUM(D25:O25) | Q25: =IFERROR(AVERAGEIF(D25:O25,"<>0"),0)
B26: Thực chi / đã nạp | C26: ='Danh mục'!D8 | D26: =SUMIFS('Sổ thu chi'!$I$5:$I$1979,'Sổ thu chi'!$B$5:$B$1979,DATE(NAM,D$3,1),'Sổ thu chi'!$C$5:$C$1979,"Chi",'Sổ thu chi'!$E$5:$E$1979,'Danh mục'!$B$8) | E26: =SUMIFS('Sổ thu chi'!$I$5:$I$1979,'Sổ thu chi'!$B$5:$B$1979,DATE(NAM,E$3,1),'Sổ thu chi'!$C$5:$C$1979,"Chi",'Sổ thu chi'!$E$5:$E$1979,'Danh mục'!$B$8) | F26: =SUMIFS('Sổ thu chi'!$I$5:$I$1979,'Sổ thu chi'!$B$5:$B$1979,DATE(NAM,F$3,1),'Sổ thu chi'!$C$5:$C$1979,"Chi",'Sổ thu chi'!$E$5:$E$1979,'Danh mục'!$B$8) | G26: =SUMIFS('Sổ thu chi'!$I$5:$I$1979,'Sổ thu chi'!$B$5:$B$1979,DATE(NAM,G$3,1),'Sổ thu chi'!$C$5:$C$1979,"Chi",'Sổ thu chi'!$E$5:$E$1979,'Danh mục'!$B$8) | H26: =SUMIFS('Sổ thu chi'!$I$5:$I$1979,'Sổ thu chi'!$B$5:$B$1979,DATE(NAM,H$3,1),'Sổ thu chi'!$C$5:$C$1979,"Chi",'Sổ thu chi'!$E$5:$E$1979,'Danh mục'!$B$8) | I26: =SUMIFS('Sổ thu chi'!$I$5:$I$1979,'Sổ thu chi'!$B$5:$B$1979,DATE(NAM,I$3,1),'Sổ thu chi'!$C$5:$C$1979,"Chi",'Sổ thu chi'!$E$5:$E$1979,'Danh mục'!$B$8) | J26: =SUMIFS('Sổ thu chi'!$I$5:$I$1979,'Sổ thu chi'!$B$5:$B$1979,DATE(NAM,J$3,1),'Sổ thu chi'!$C$5:$C$1979,"Chi",'Sổ thu chi'!$E$5:$E$1979,'Danh mục'!$B$8) | K26: =SUMIFS('Sổ thu chi'!$I$5:$I$1979,'Sổ thu chi'!$B$5:$B$1979,DATE(NAM,K$3,1),'Sổ thu chi'!$C$5:$C$1979,"Chi",'Sổ thu chi'!$E$5:$E$1979,'Danh mục'!$B$8) | ... O26: =SUMIFS('Sổ thu chi'!$I$5:$I$1979,'Sổ thu chi'!$B$5:$B$1979,DATE(NAM,O$3,1),'Sổ thu chi'!$C$5:$C$1979,"Chi",'Sổ thu chi'!$E$5:$E$1979,'Danh mục'!$B$8) | P26: =SUM(D26:O26) | Q26: =IFERROR(AVERAGEIF(D26:O26,"<>0"),0)
B27: Còn lại | D27: =D25-D26 | E27: =E25-E26 | F27: =F25-F26 | G27: =G25-G26 | H27: =H25-H26 | I27: =I25-I26 | J27: =J25-J26 | K27: =K25-K26 | ... O27: =O25-O26 | P27: =SUM(D27:O27)
A28: 3 | B28: ='Danh mục'!B9&" – Ngân sách" | C28: ='Danh mục'!C9 | D28: =D$16*'Danh mục'!$C$9 | E28: =E$16*'Danh mục'!$C$9 | F28: =F$16*'Danh mục'!$C$9 | G28: =G$16*'Danh mục'!$C$9 | H28: =H$16*'Danh mục'!$C$9 | I28: =I$16*'Danh mục'!$C$9 | J28: =J$16*'Danh mục'!$C$9 | K28: =K$16*'Danh mục'!$C$9 | ... O28: =O$16*'Danh mục'!$C$9 | P28: =SUM(D28:O28) | Q28: =IFERROR(AVERAGEIF(D28:O28,"<>0"),0)
B29: Thực chi / đã nạp | C29: ='Danh mục'!D9 | D29: =SUMIFS('Sổ thu chi'!$I$5:$I$1979,'Sổ thu chi'!$B$5:$B$1979,DATE(NAM,D$3,1),'Sổ thu chi'!$C$5:$C$1979,"Chi",'Sổ thu chi'!$E$5:$E$1979,'Danh mục'!$B$9) | E29: =SUMIFS('Sổ thu chi'!$I$5:$I$1979,'Sổ thu chi'!$B$5:$B$1979,DATE(NAM,E$3,1),'Sổ thu chi'!$C$5:$C$1979,"Chi",'Sổ thu chi'!$E$5:$E$1979,'Danh mục'!$B$9) | F29: =SUMIFS('Sổ thu chi'!$I$5:$I$1979,'Sổ thu chi'!$B$5:$B$1979,DATE(NAM,F$3,1),'Sổ thu chi'!$C$5:$C$1979,"Chi",'Sổ thu chi'!$E$5:$E$1979,'Danh mục'!$B$9) | G29: =SUMIFS('Sổ thu chi'!$I$5:$I$1979,'Sổ thu chi'!$B$5:$B$1979,DATE(NAM,G$3,1),'Sổ thu chi'!$C$5:$C$1979,"Chi",'Sổ thu chi'!$E$5:$E$1979,'Danh mục'!$B$9) | H29: =SUMIFS('Sổ thu chi'!$I$5:$I$1979,'Sổ thu chi'!$B$5:$B$1979,DATE(NAM,H$3,1),'Sổ thu chi'!$C$5:$C$1979,"Chi",'Sổ thu chi'!$E$5:$E$1979,'Danh mục'!$B$9) | I29: =SUMIFS('Sổ thu chi'!$I$5:$I$1979,'Sổ thu chi'!$B$5:$B$1979,DATE(NAM,I$3,1),'Sổ thu chi'!$C$5:$C$1979,"Chi",'Sổ thu chi'!$E$5:$E$1979,'Danh mục'!$B$9) | J29: =SUMIFS('Sổ thu chi'!$I$5:$I$1979,'Sổ thu chi'!$B$5:$B$1979,DATE(NAM,J$3,1),'Sổ thu chi'!$C$5:$C$1979,"Chi",'Sổ thu chi'!$E$5:$E$1979,'Danh mục'!$B$9) | K29: =SUMIFS('Sổ thu chi'!$I$5:$I$1979,'Sổ thu chi'!$B$5:$B$1979,DATE(NAM,K$3,1),'Sổ thu chi'!$C$5:$C$1979,"Chi",'Sổ thu chi'!$E$5:$E$1979,'Danh mục'!$B$9) | ... O29: =SUMIFS('Sổ thu chi'!$I$5:$I$1979,'Sổ thu chi'!$B$5:$B$1979,DATE(NAM,O$3,1),'Sổ thu chi'!$C$5:$C$1979,"Chi",'Sổ thu chi'!$E$5:$E$1979,'Danh mục'!$B$9) | P29: =SUM(D29:O29) | Q29: =IFERROR(AVERAGEIF(D29:O29,"<>0"),0)
B30: Còn lại | D30: =D28-D29 | E30: =E28-E29 | F30: =F28-F29 | G30: =G28-G29 | H30: =H28-H29 | I30: =I28-I29 | J30: =J28-J29 | K30: =K28-K29 | ... O30: =O28-O29 | P30: =SUM(D30:O30)
A31: 4 | B31: ='Danh mục'!B10&" – Ngân sách" | C31: ='Danh mục'!C10 | D31: =D$16*'Danh mục'!$C$10 | E31: =E$16*'Danh mục'!$C$10 | F31: =F$16*'Danh mục'!$C$10 | G31: =G$16*'Danh mục'!$C$10 | H31: =H$16*'Danh mục'!$C$10 | I31: =I$16*'Danh mục'!$C$10 | J31: =J$16*'Danh mục'!$C$10 | K31: =K$16*'Danh mục'!$C$10 | ... O31: =O$16*'Danh mục'!$C$10 | P31: =SUM(D31:O31) | Q31: =IFERROR(AVERAGEIF(D31:O31,"<>0"),0)
B32: Thực chi / đã nạp | C32: ='Danh mục'!D10 | D32: =SUMIFS('Sổ thu chi'!$I$5:$I$1979,'Sổ thu chi'!$B$5:$B$1979,DATE(NAM,D$3,1),'Sổ thu chi'!$C$5:$C$1979,"Chi",'Sổ thu chi'!$E$5:$E$1979,'Danh mục'!$B$10) | E32: =SUMIFS('Sổ thu chi'!$I$5:$I$1979,'Sổ thu chi'!$B$5:$B$1979,DATE(NAM,E$3,1),'Sổ thu chi'!$C$5:$C$1979,"Chi",'Sổ thu chi'!$E$5:$E$1979,'Danh mục'!$B$10) | F32: =SUMIFS('Sổ thu chi'!$I$5:$I$1979,'Sổ thu chi'!$B$5:$B$1979,DATE(NAM,F$3,1),'Sổ thu chi'!$C$5:$C$1979,"Chi",'Sổ thu chi'!$E$5:$E$1979,'Danh mục'!$B$10) | G32: =SUMIFS('Sổ thu chi'!$I$5:$I$1979,'Sổ thu chi'!$B$5:$B$1979,DATE(NAM,G$3,1),'Sổ thu chi'!$C$5:$C$1979,"Chi",'Sổ thu chi'!$E$5:$E$1979,'Danh mục'!$B$10) | H32: =SUMIFS('Sổ thu chi'!$I$5:$I$1979,'Sổ thu chi'!$B$5:$B$1979,DATE(NAM,H$3,1),'Sổ thu chi'!$C$5:$C$1979,"Chi",'Sổ thu chi'!$E$5:$E$1979,'Danh mục'!$B$10) | I32: =SUMIFS('Sổ thu chi'!$I$5:$I$1979,'Sổ thu chi'!$B$5:$B$1979,DATE(NAM,I$3,1),'Sổ thu chi'!$C$5:$C$1979,"Chi",'Sổ thu chi'!$E$5:$E$1979,'Danh mục'!$B$10) | J32: =SUMIFS('Sổ thu chi'!$I$5:$I$1979,'Sổ thu chi'!$B$5:$B$1979,DATE(NAM,J$3,1),'Sổ thu chi'!$C$5:$C$1979,"Chi",'Sổ thu chi'!$E$5:$E$1979,'Danh mục'!$B$10) | K32: =SUMIFS('Sổ thu chi'!$I$5:$I$1979,'Sổ thu chi'!$B$5:$B$1979,DATE(NAM,K$3,1),'Sổ thu chi'!$C$5:$C$1979,"Chi",'Sổ thu chi'!$E$5:$E$1979,'Danh mục'!$B$10) | ... O32: =SUMIFS('Sổ thu chi'!$I$5:$I$1979,'Sổ thu chi'!$B$5:$B$1979,DATE(NAM,O$3,1),'Sổ thu chi'!$C$5:$C$1979,"Chi",'Sổ thu chi'!$E$5:$E$1979,'Danh mục'!$B$10) | P32: =SUM(D32:O32) | Q32: =IFERROR(AVERAGEIF(D32:O32,"<>0"),0)
B33: Còn lại | D33: =D31-D32 | E33: =E31-E32 | F33: =F31-F32 | G33: =G31-G32 | H33: =H31-H32 | I33: =I31-I32 | J33: =J31-J32 | K33: =K31-K32 | ... O33: =O31-O32 | P33: =SUM(D33:O33)
A34: 5 | B34: ='Danh mục'!B11&" – Ngân sách" | C34: ='Danh mục'!C11 | D34: =D$16*'Danh mục'!$C$11 | E34: =E$16*'Danh mục'!$C$11 | F34: =F$16*'Danh mục'!$C$11 | G34: =G$16*'Danh mục'!$C$11 | H34: =H$16*'Danh mục'!$C$11 | I34: =I$16*'Danh mục'!$C$11 | J34: =J$16*'Danh mục'!$C$11 | K34: =K$16*'Danh mục'!$C$11 | ... O34: =O$16*'Danh mục'!$C$11 | P34: =SUM(D34:O34) | Q34: =IFERROR(AVERAGEIF(D34:O34,"<>0"),0)
B35: Thực chi / đã nạp | C35: ='Danh mục'!D11 | D35: =SUMIFS('Sổ thu chi'!$I$5:$I$1979,'Sổ thu chi'!$B$5:$B$1979,DATE(NAM,D$3,1),'Sổ thu chi'!$C$5:$C$1979,"Chi",'Sổ thu chi'!$E$5:$E$1979,'Danh mục'!$B$11) | E35: =SUMIFS('Sổ thu chi'!$I$5:$I$1979,'Sổ thu chi'!$B$5:$B$1979,DATE(NAM,E$3,1),'Sổ thu chi'!$C$5:$C$1979,"Chi",'Sổ thu chi'!$E$5:$E$1979,'Danh mục'!$B$11) | F35: =SUMIFS('Sổ thu chi'!$I$5:$I$1979,'Sổ thu chi'!$B$5:$B$1979,DATE(NAM,F$3,1),'Sổ thu chi'!$C$5:$C$1979,"Chi",'Sổ thu chi'!$E$5:$E$1979,'Danh mục'!$B$11) | G35: =SUMIFS('Sổ thu chi'!$I$5:$I$1979,'Sổ thu chi'!$B$5:$B$1979,DATE(NAM,G$3,1),'Sổ thu chi'!$C$5:$C$1979,"Chi",'Sổ thu chi'!$E$5:$E$1979,'Danh mục'!$B$11) | H35: =SUMIFS('Sổ thu chi'!$I$5:$I$1979,'Sổ thu chi'!$B$5:$B$1979,DATE(NAM,H$3,1),'Sổ thu chi'!$C$5:$C$1979,"Chi",'Sổ thu chi'!$E$5:$E$1979,'Danh mục'!$B$11) | I35: =SUMIFS('Sổ thu chi'!$I$5:$I$1979,'Sổ thu chi'!$B$5:$B$1979,DATE(NAM,I$3,1),'Sổ thu chi'!$C$5:$C$1979,"Chi",'Sổ thu chi'!$E$5:$E$1979,'Danh mục'!$B$11) | J35: =SUMIFS('Sổ thu chi'!$I$5:$I$1979,'Sổ thu chi'!$B$5:$B$1979,DATE(NAM,J$3,1),'Sổ thu chi'!$C$5:$C$1979,"Chi",'Sổ thu chi'!$E$5:$E$1979,'Danh mục'!$B$11) | K35: =SUMIFS('Sổ thu chi'!$I$5:$I$1979,'Sổ thu chi'!$B$5:$B$1979,DATE(NAM,K$3,1),'Sổ thu chi'!$C$5:$C$1979,"Chi",'Sổ thu chi'!$E$5:$E$1979,'Danh mục'!$B$11) | ... O35: =SUMIFS('Sổ thu chi'!$I$5:$I$1979,'Sổ thu chi'!$B$5:$B$1979,DATE(NAM,O$3,1),'Sổ thu chi'!$C$5:$C$1979,"Chi",'Sổ thu chi'!$E$5:$E$1979,'Danh mục'!$B$11) | P35: =SUM(D35:O35) | Q35: =IFERROR(AVERAGEIF(D35:O35,"<>0"),0)
B36: Còn lại | D36: =D34-D35 | E36: =E34-E35 | F36: =F34-F35 | G36: =G34-G35 | H36: =H34-H35 | I36: =I34-I35 | J36: =J34-J35 | K36: =K34-K35 | ... O36: =O34-O35 | P36: =SUM(D36:O36)
A37: 6 | B37: ='Danh mục'!B12&" – Ngân sách" | C37: ='Danh mục'!C12 | D37: =D$16*'Danh mục'!$C$12 | E37: =E$16*'Danh mục'!$C$12 | F37: =F$16*'Danh mục'!$C$12 | G37: =G$16*'Danh mục'!$C$12 | H37: =H$16*'Danh mục'!$C$12 | I37: =I$16*'Danh mục'!$C$12 | J37: =J$16*'Danh mục'!$C$12 | K37: =K$16*'Danh mục'!$C$12 | ... O37: =O$16*'Danh mục'!$C$12 | P37: =SUM(D37:O37) | Q37: =IFERROR(AVERAGEIF(D37:O37,"<>0"),0)
B38: Thực chi / đã nạp | C38: ='Danh mục'!D12 | D38: =SUMIFS('Sổ thu chi'!$I$5:$I$1979,'Sổ thu chi'!$B$5:$B$1979,DATE(NAM,D$3,1),'Sổ thu chi'!$C$5:$C$1979,"Chi",'Sổ thu chi'!$E$5:$E$1979,'Danh mục'!$B$12) | E38: =SUMIFS('Sổ thu chi'!$I$5:$I$1979,'Sổ thu chi'!$B$5:$B$1979,DATE(NAM,E$3,1),'Sổ thu chi'!$C$5:$C$1979,"Chi",'Sổ thu chi'!$E$5:$E$1979,'Danh mục'!$B$12) | F38: =SUMIFS('Sổ thu chi'!$I$5:$I$1979,'Sổ thu chi'!$B$5:$B$1979,DATE(NAM,F$3,1),'Sổ thu chi'!$C$5:$C$1979,"Chi",'Sổ thu chi'!$E$5:$E$1979,'Danh mục'!$B$12) | G38: =SUMIFS('Sổ thu chi'!$I$5:$I$1979,'Sổ thu chi'!$B$5:$B$1979,DATE(NAM,G$3,1),'Sổ thu chi'!$C$5:$C$1979,"Chi",'Sổ thu chi'!$E$5:$E$1979,'Danh mục'!$B$12) | H38: =SUMIFS('Sổ thu chi'!$I$5:$I$1979,'Sổ thu chi'!$B$5:$B$1979,DATE(NAM,H$3,1),'Sổ thu chi'!$C$5:$C$1979,"Chi",'Sổ thu chi'!$E$5:$E$1979,'Danh mục'!$B$12) | I38: =SUMIFS('Sổ thu chi'!$I$5:$I$1979,'Sổ thu chi'!$B$5:$B$1979,DATE(NAM,I$3,1),'Sổ thu chi'!$C$5:$C$1979,"Chi",'Sổ thu chi'!$E$5:$E$1979,'Danh mục'!$B$12) | J38: =SUMIFS('Sổ thu chi'!$I$5:$I$1979,'Sổ thu chi'!$B$5:$B$1979,DATE(NAM,J$3,1),'Sổ thu chi'!$C$5:$C$1979,"Chi",'Sổ thu chi'!$E$5:$E$1979,'Danh mục'!$B$12) | K38: =SUMIFS('Sổ thu chi'!$I$5:$I$1979,'Sổ thu chi'!$B$5:$B$1979,DATE(NAM,K$3,1),'Sổ thu chi'!$C$5:$C$1979,"Chi",'Sổ thu chi'!$E$5:$E$1979,'Danh mục'!$B$12) | ... O38: =SUMIFS('Sổ thu chi'!$I$5:$I$1979,'Sổ thu chi'!$B$5:$B$1979,DATE(NAM,O$3,1),'Sổ thu chi'!$C$5:$C$1979,"Chi",'Sổ thu chi'!$E$5:$E$1979,'Danh mục'!$B$12) | P38: =SUM(D38:O38) | Q38: =IFERROR(AVERAGEIF(D38:O38,"<>0"),0)
B39: Còn lại | D39: =D37-D38 | E39: =E37-E38 | F39: =F37-F38 | G39: =G37-G38 | H39: =H37-H38 | I39: =I37-I38 | J39: =J37-J38 | K39: =K37-K38 | ... O39: =O37-O38 | P39: =SUM(D39:O39)
B40: TỔNG CHI | D40: =D23+D26+D29+D32+D35+D38 | E40: =E23+E26+E29+E32+E35+E38 | F40: =F23+F26+F29+F32+F35+F38 | G40: =G23+G26+G29+G32+G35+G38 | H40: =H23+H26+H29+H32+H35+H38 | I40: =I23+I26+I29+I32+I35+I38 | J40: =J23+J26+J29+J32+J35+J38 | K40: =K23+K26+K29+K32+K35+K38 | ... O40: =O23+O26+O29+O32+O35+O38 | P40: =SUM(D40:O40) | Q40: =IFERROR(AVERAGEIF(D40:O40,"<>0"),0)
A42: III. CHI TIẾT THEO DANH MỤC CHI
...

Sheet Danh mục
A1: DANH MỤC & THIẾT LẬP
A2: Ô vàng chữ xanh = được sửa. Ô xám = tự tính. Thêm danh mục: nhập liền nhau từ trên xuống, không bỏ trống ở giữa.
A3: Năm theo dõi | C3: 2026
A5: 1. TỶ LỆ 6 HŨ (phân bổ theo thu nhập tháng)
A6: Mã | B6: Tên hũ | C6: Tỷ lệ | D6: Loại hũ | E6: Dùng cho
A7: NEC | B7: Thiết yếu | C7: 0.55 | D7: Chi tiêu | E7: Ăn uống, nhà ở, điện nước, đi lại, y tế, bảo hiểm, sữa bỉm & học phí chính khóa của con
A8: FFA | B8: Tự do tài chính | C8: 0.1 | D8: Tích lũy | E8: Đầu tư sinh lời: chứng khoán, CCQ, vàng, kinh doanh – không tiêu
A9: LTSS | B9: Tiết kiệm dài hạn | C9: 0.1 | D9: Tích lũy | E9: Quỹ khẩn cấp (6 tháng chi thiết yếu), mua nhà, xe, quỹ học vấn cho con
A10: EDU | B10: Giáo dục | C10: 0.1 | D10: Chi tiêu | E10: Sách, khóa học của bố mẹ; học thêm, năng khiếu của con
A11: PLAY | B11: Hưởng thụ | C11: 0.1 | D11: Chi tiêu | E11: Du lịch, giải trí, nhà hàng, mua sắm cá nhân
A12: GIVE | B12: Cho đi | C12: 0.05 | D12: Chi tiêu | E12: Biếu bố mẹ, hiếu hỷ, từ thiện, quà tặng
B13: Tổng | C13: =SUM(C7:C12) | D13: =IF(ROUND(C13,4)=1,"✔ Hợp lệ","⚠ Tổng phải = 100%")
A15: 2. NGƯỜI THU/CHI & HÌNH THỨC THANH TOÁN
A16: Người | D16: Hình thức TT
A17: Chồng | D17: Tiền mặt
A18: Vợ | D18: Chuyển khoản
A19: Con | D19: Thẻ tín dụng
A20: Chung | D20: Ví điện tử
A24: 3. DANH MỤC THU
A25: Danh mục thu | B25: Tính chất | C25: Ghi chú | G25: Nguồn dropdown Danh mục (tự động, không sửa)
A26: Lương | B26: Thu nhập | C26: Ghi riêng từng người ở cột 'Người' | G26: =IF(1<=COUNTA($A$26:$A$35),INDEX($A$26:$A$35,1),IF(1-COUNTA($A$26:$A$35)<=COUNTA($A$39:$A$78),INDEX($A$39:$A$78,1-COUNTA($A$26:$A$35)),""))
A27: Thưởng | B27: Thu nhập | G27: =IF(2<=COUNTA($A$26:$A$35),INDEX($A$26:$A$35,2),IF(2-COUNTA($A$26:$A$35)<=COUNTA($A$39:$A$78),INDEX($A$39:$A$78,2-COUNTA($A$26:$A$35)),""))
A28: Làm thêm / kinh doanh | B28: Thu nhập | G28: =IF(3<=COUNTA($A$26:$A$35),INDEX($A$26:$A$35,3),IF(3-COUNTA($A$26:$A$35)<=COUNTA($A$39:$A$78),INDEX($A$39:$A$78,3-COUNTA($A$26:$A$35)),""))
A29: Lãi tiết kiệm / cổ tức | B29: Thu nhập | G29: =IF(4<=COUNTA($A$26:$A$35),INDEX($A$26:$A$35,4),IF(4-COUNTA($A$26:$A$35)<=COUNTA($A$39:$A$78),INDEX($A$39:$A$78,4-COUNTA($A$26:$A$35)),""))
A30: Được biếu / mừng | B30: Thu nhập | G30: =IF(5<=COUNTA($A$26:$A$35),INDEX($A$26:$A$35,5),IF(5-COUNTA($A$26:$A$35)<=COUNTA($A$39:$A$78),INDEX($A$39:$A$78,5-COUNTA($A$26:$A$35)),""))
A31: Thu khác | B31: Thu nhập | G31: =IF(6<=COUNTA($A$26:$A$35),INDEX($A$26:$A$35,6),IF(6-COUNTA($A$26:$A$35)<=COUNTA($A$39:$A$78),INDEX($A$39:$A$78,6-COUNTA($A$26:$A$35)),""))
A32: Rút tiền tiết kiệm | B32: Rút quỹ | C32: Không tính vào thu nhập để chia hũ | G32: =IF(7<=COUNTA($A$26:$A$35),INDEX($A$26:$A$35,7),IF(7-COUNTA($A$26:$A$35)<=COUNTA($A$39:$A$78),INDEX($A$39:$A$78,7-COUNTA($A$26:$A$35)),""))
A33: Điều chuyển nợ thẻ TD (không tính) | B33: Không tính | C33: Thanh toán thẻ, chuyển trả góp – không tính vào thu/chi | G33: =IF(8<=COUNTA($A$26:$A$35),INDEX($A$26:$A$35,8),IF(8-COUNTA($A$26:$A$35)<=COUNTA($A$39:$A$78),INDEX($A$39:$A$78,8-COUNTA($A$26:$A$35)),""))
G34: =IF(9<=COUNTA($A$26:$A$35),INDEX($A$26:$A$35,9),IF(9-COUNTA($A$26:$A$35)<=COUNTA($A$39:$A$78),INDEX($A$39:$A$78,9-COUNTA($A$26:$A$35)),""))
G35: =IF(10<=COUNTA($A$26:$A$35),INDEX($A$26:$A$35,10),IF(10-COUNTA($A$26:$A$35)<=COUNTA($A$39:$A$78),INDEX($A$39:$A$78,10-COUNTA($A$26:$A$35)),""))
G36: =IF(11<=COUNTA($A$26:$A$35),INDEX($A$26:$A$35,11),IF(11-COUNTA($A$26:$A$35)<=COUNTA($A$39:$A$78),INDEX($A$39:$A$78,11-COUNTA($A$26:$A$35)),""))
A37: 4. DANH MỤC CHI | G37: =IF(12<=COUNTA($A$26:$A$35),INDEX($A$26:$A$35,12),IF(12-COUNTA($A$26:$A$35)<=COUNTA($A$39:$A$78),INDEX($A$39:$A$78,12-COUNTA($A$26:$A$35)),""))
A38: Danh mục chi | B38: Hũ | C38: Nhóm | D38: Tính chất (tự động) | E38: Hạn mức/tháng (tùy chọn) | G38: =IF(13<=COUNTA($A$26:$A$35),INDEX($A$26:$A$35,13),IF(13-COUNTA($A$26:$A$35)<=COUNTA($A$39:$A$78),INDEX($A$39:$A$78,13-COUNTA($A$26:$A$35)),""))
A39: Đi chợ, ăn uống tại nhà | B39: Thiết yếu | C39: Gia đình | D39: =IF(A39="","",IFERROR(INDEX($D$7:$D$12,MATCH(B39,$B$7:$B$12,0)),"?")) | G39: =IF(14<=COUNTA($A$26:$A$35),INDEX($A$26:$A$35,14),IF(14-COUNTA($A$26:$A$35)<=COUNTA($A$39:$A$78),INDEX($A$39:$A$78,14-COUNTA($A$26:$A$35)),""))
A40: Ăn sáng, ăn trưa đi làm | B40: Thiết yếu | C40: Gia đình | D40: =IF(A40="","",IFERROR(INDEX($D$7:$D$12,MATCH(B40,$B$7:$B$12,0)),"?")) | G40: =IF(15<=COUNTA($A$26:$A$35),INDEX($A$26:$A$35,15),IF(15-COUNTA($A$26:$A$35)<=COUNTA($A$39:$A$78),INDEX($A$39:$A$78,15-COUNTA($A$26:$A$35)),""))
A41: Điện | B41: Thiết yếu | C41: Gia đình | D41: =IF(A41="","",IFERROR(INDEX($D$7:$D$12,MATCH(B41,$B$7:$B$12,0)),"?")) | G41: =IF(16<=COUNTA($A$26:$A$35),INDEX($A$26:$A$35,16),IF(16-COUNTA($A$26:$A$35)<=COUNTA($A$39:$A$78),INDEX($A$39:$A$78,16-COUNTA($A$26:$A$35)),""))
A42: Nước | B42: Thiết yếu | C42: Gia đình | D42: =IF(A42="","",IFERROR(INDEX($D$7:$D$12,MATCH(B42,$B$7:$B$12,0)),"?")) | G42: =IF(17<=COUNTA($A$26:$A$35),INDEX($A$26:$A$35,17),IF(17-COUNTA($A$26:$A$35)<=COUNTA($A$39:$A$78),INDEX($A$39:$A$78,17-COUNTA($A$26:$A$35)),""))
A43: Internet, điện thoại, truyền hình | B43: Thiết yếu | C43: Gia đình | D43: =IF(A43="","",IFERROR(INDEX($D$7:$D$12,MATCH(B43,$B$7:$B$12,0)),"?")) | G43: =IF(18<=COUNTA($A$26:$A$35),INDEX($A$26:$A$35,18),IF(18-COUNTA($A$26:$A$35)<=COUNTA($A$39:$A$78),INDEX($A$39:$A$78,18-COUNTA($A$26:$A$35)),""))
A44: Gas, đồ dùng sinh hoạt | B44: Thiết yếu | C44: Gia đình | D44: =IF(A44="","",IFERROR(INDEX($D$7:$D$12,MATCH(B44,$B$7:$B$12,0)),"?")) | G44: =IF(19<=COUNTA($A$26:$A$35),INDEX($A$26:$A$35,19),IF(19-COUNTA($A$26:$A$35)<=COUNTA($A$39:$A$78),INDEX($A$39:$A$78,19-COUNTA($A$26:$A$35)),""))
A45: Xăng xe, gửi xe, đi lại | B45: Thiết yếu | C45: Gia đình | D45: =IF(A45="","",IFERROR(INDEX($D$7:$D$12,MATCH(B45,$B$7:$B$12,0)),"?")) | G45: =IF(20<=COUNTA($A$26:$A$35),INDEX($A$26:$A$35,20),IF(20-COUNTA($A$26:$A$35)<=COUNTA($A$39:$A$78),INDEX($A$39:$A$78,20-COUNTA($A$26:$A$35)),""))
...
